Workbook
Name chart_Week: INDEX(History!$A$56:$A$165,MAX(1,COUNT(History!$A$56:$A$165)-25)):INDEX(History!$A$56:$A$165,MAX(1,COUNT(History!$A$56:$A$165)))
Name chart_BVR: INDEX(History!$B$56:$B$165,MAX(1,COUNT(History!$A$56:$A$165)-25)):INDEX(History!$B$56:$B$165,MAX(1,COUNT(History!$A$56:$A$165)))
Name chart_BVP: INDEX(History!$C$56:$C$165,MAX(1,COUNT(History!$A$56:$A$165)-25)):INDEX(History!$C$56:$C$165,MAX(1,COUNT(History!$A$56:$A$165)))
Name chart_BVT: INDEX(History!$D$56:$D$165,MAX(1,COUNT(History!$A$56:$A$165)-25)):INDEX(History!$D$56:$D$165,MAX(1,COUNT(History!$A$56:$A$165)))
Name chart_LVR: INDEX(History!$E$56:$E$165,MAX(1,COUNT(History!$A$56:$A$165)-25)):INDEX(History!$E$56:$E$165,MAX(1,COUNT(History!$A$56:$A$165)))
Name chart_LVP: INDEX(History!$F$56:$F$165,MAX(1,COUNT(History!$A$56:$A$165)-25)):INDEX(History!$F$56:$F$165,MAX(1,COUNT(History!$A$56:$A$165)))
Name chart_LVT: INDEX(History!$G$56:$G$165,MAX(1,COUNT(History!$A$56:$A$165)-25)):INDEX(History!$G$56:$G$165,MAX(1,COUNT(History!$A$56:$A$165)))
Name chart_REPT: INDEX(History!$H$56:$H$165,MAX(1,COUNT(History!$A$56:$A$165)-25)):INDEX(History!$H$56:$H$165,MAX(1,COUNT(History!$A$56:$A$165)))
Name chart_PMT: INDEX(History!$I$56:$I$165,MAX(1,COUNT(History!$A$56:$A$165)-25)):INDEX(History!$I$56:$I$165,MAX(1,COUNT(History!$A$56:$A$165)))
Name chart_CO: INDEX(History!$J$56:$J$165,MAX(1,COUNT(History!$A$56:$A$165)-25)):INDEX(History!$J$56:$J$165,MAX(1,COUNT(History!$A$56:$A$165)))
Name last_BVR: IF(History!chart_Week=MAX(History!chart_Week),History!chart_BVR,NA())
Name last_BVP: IF(History!chart_Week=MAX(History!chart_Week),History!chart_BVP,NA())
Name last_BVT: IF(History!chart_Week=MAX(History!chart_Week),History!chart_BVT,NA())
Name last_LVR: IF(History!chart_Week=MAX(History!chart_Week),History!chart_LVR,NA())
Name last_LVP: IF(History!chart_Week=MAX(History!chart_Week),History!chart_LVP,NA())
Name last_LVT: IF(History!chart_Week=MAX(History!chart_Week),History!chart_LVT,NA())
Name last_REPT: IF(History!chart_Week=MAX(History!chart_Week),History!chart_REPT,NA())
Name last_PMT: IF(History!chart_Week=MAX(History!chart_Week),History!chart_PMT,NA())
Name last_CO: IF(History!chart_Week=MAX(History!chart_Week),History!chart_CO,NA())

Sheet History
A1: OPEN WORK ORDERS — WEEKLY HISTORY | N1: =COUNT($A$56:$A$165)
A2: Buddy's Kitchen · Burnsville and Lakeville · type this week's counts on the Totals tab and everything below updates itself | N2: =IF($N$1=0,"",INDEX($A$56:$A$165,$N$1))
A3: =IF($N$1=0,"No weeks entered yet — start on the Totals tab.","Week of "&TEXT($N$2,"mmmm d, yyyy")&": "&TEXT($D$8,"#,##0")&" open repair tickets"&IF($F$8=""," (first week on record)"," ("&IF($F$8>0,"up "&TEXT($F$8,"#,##0"),IF($F$8<0,"down "&TEXT(-$F$8,"#,##0"),"unchanged"))&" "&$N$7&")")&". PMs "&TEXT($D$12,"#,##0")&IF($F$12=""," "," ("&IF($F$12>0,"up "&TEXT($F$12,"#,##0"),IF($F$12<0,"down "&TEXT(-$F$12,"#,##0"),"unchanged"))&").")&" All open "&TEXT($D$16,"#,##0")&".") | N3: =Totals!$C$33
A4: =IF(Totals!$F$33>0,"⚠ Two or more week blocks on the Totals tab carry the same date. Fix that before sending this out — one of them is a phantom week.",IF(Totals!$E$33>0,"⚠ "&TEXT(Totals!$E$33,"0")&" week block(s) on the Totals tab are part-filled, so they are being left out of the history. Every week needs all four counts and a date.",IF($N$1>=110,"⚠ The weekly log is full. Add rows before entering another week — see the Read Me tab.",""))) | N4: =Totals!$D$33
D5: This week | E5: Previous entry | F5: Change | G5: 4-week avg | N5: =IF('Read Me'!$C$37="","(paste the file link — see the Read Me tab)",'Read Me'!$C$37)
A6: Open repair tickets — Burnsville | D6: =IF($N$1=0,"",INDEX($B$56:$B$165,$N$1)) | E6: =IF($N$1<2,"",INDEX($B$56:$B$165,$N$1-1)) | F6: =IF(OR(D6="",E6=""),"",D6-E6) | G6: =IF($N$1=0,"",AVERAGE(INDEX($B$56:$B$165,MAX(1,$N$1-3)):INDEX($B$56:$B$165,$N$1))) | N6: =IF($N$1<2,"",INDEX($A$56:$A$165,$N$1)-INDEX($A$56:$A$165,$N$1-1))
A7: Open repair tickets — Lakeville | D7: =IF($N$1=0,"",INDEX($E$56:$E$165,$N$1)) | E7: =IF($N$1<2,"",INDEX($E$56:$E$165,$N$1-1)) | F7: =IF(OR(D7="",E7=""),"",D7-E7) | G7: =IF($N$1=0,"",AVERAGE(INDEX($E$56:$E$165,MAX(1,$N$1-3)):INDEX($E$56:$E$165,$N$1))) | N7: =IF($N$6="","",IF($N$6=7,"vs last week","vs the previous entry, "&TEXT($N$6,"0")&" days earlier"))
A8: OPEN REPAIR TICKETS — BOTH PLANTS | D8: =IF($N$1=0,"",INDEX($H$56:$H$165,$N$1)) | E8: =IF($N$1<2,"",INDEX($H$56:$H$165,$N$1-1)) | F8: =IF(OR(D8="",E8=""),"",D8-E8) | G8: =IF($N$1=0,"",AVERAGE(INDEX($H$56:$H$165,MAX(1,$N$1-3)):INDEX($H$56:$H$165,$N$1)))
A10: Open PMs — Burnsville | D10: =IF($N$1=0,"",INDEX($C$56:$C$165,$N$1)) | E10: =IF($N$1<2,"",INDEX($C$56:$C$165,$N$1-1)) | F10: =IF(OR(D10="",E10=""),"",D10-E10) | G10: =IF($N$1=0,"",AVERAGE(INDEX($C$56:$C$165,MAX(1,$N$1-3)):INDEX($C$56:$C$165,$N$1)))
A11: Open PMs — Lakeville | D11: =IF($N$1=0,"",INDEX($F$56:$F$165,$N$1)) | E11: =IF($N$1<2,"",INDEX($F$56:$F$165,$N$1-1)) | F11: =IF(OR(D11="",E11=""),"",D11-E11) | G11: =IF($N$1=0,"",AVERAGE(INDEX($F$56:$F$165,MAX(1,$N$1-3)):INDEX($F$56:$F$165,$N$1)))
A12: Open PMs — both plants | D12: =IF($N$1=0,"",INDEX($I$56:$I$165,$N$1)) | E12: =IF($N$1<2,"",INDEX($I$56:$I$165,$N$1-1)) | F12: =IF(OR(D12="",E12=""),"",D12-E12) | G12: =IF($N$1=0,"",AVERAGE(INDEX($I$56:$I$165,MAX(1,$N$1-3)):INDEX($I$56:$I$165,$N$1)))
A14: All open work orders — Burnsville | D14: =IF($N$1=0,"",INDEX($D$56:$D$165,$N$1)) | E14: =IF($N$1<2,"",INDEX($D$56:$D$165,$N$1-1)) | F14: =IF(OR(D14="",E14=""),"",D14-E14) | G14: =IF($N$1=0,"",AVERAGE(INDEX($D$56:$D$165,MAX(1,$N$1-3)):INDEX($D$56:$D$165,$N$1)))
A15: All open work orders — Lakeville | D15: =IF($N$1=0,"",INDEX($G$56:$G$165,$N$1)) | E15: =IF($N$1<2,"",INDEX($G$56:$G$165,$N$1-1)) | F15: =IF(OR(D15="",E15=""),"",D15-E15) | G15: =IF($N$1=0,"",AVERAGE(INDEX($G$56:$G$165,MAX(1,$N$1-3)):INDEX($G$56:$G$165,$N$1)))
A16: All open work orders — both plants | D16: =IF($N$1=0,"",INDEX($J$56:$J$165,$N$1)) | E16: =IF($N$1<2,"",INDEX($J$56:$J$165,$N$1-1)) | F16: =IF(OR(D16="",E16=""),"",D16-E16) | G16: =IF($N$1=0,"",AVERAGE(INDEX($J$56:$J$165,MAX(1,$N$1-3)):INDEX($J$56:$J$165,$N$1)))
A17: ▲ = more open than the previous entry · ▼ = fewer. Only the repair rows are coloured: PMs jump whenever the maintenance system releases a batch, which is not a backlog problem, so repair tickets are the line to watch.
A18: =HYPERLINK("#Totals!"&ADDRESS(4,Totals!$B$33,4),"► Enter this week's counts on the Totals tab")
A19: TREND — the most recent 26 weeks (every week is in the log below)
F36: COPY THIS INTO THE WEEKLY EMAIL — click the cell, copy, then in Outlook paste with Keep Text Only
F37: =IF($N$1=0,"Enter a week on the Totals tab and this fills in.","Open work orders — week of "&TEXT($N$2,"mm/dd/yyyy")&CHAR(10)&CHAR(10)&"Repair tickets: "&TEXT($D$8,"#,##0")&" ("&IF($F$8="","n/a",IF($F$8>0,"+"&TEXT($F$8,"#,##0"),IF($F$8<0,TEXT($F$8,"#,##0"),"no change")))&" "&$N$7&")"&CHAR(10)&"PMs: "&TEXT($D$12,"#,##0")&" ("&IF($F$12="","n/a",IF($F$12>0,"+"&TEXT($F$12,"#,##0"),IF($F$12<0,TEXT($F$12,"#,##0"),"no change")))&")"&CHAR(10)&"All open: "&TEXT($D$16,"#,##0")&" ("&IF($F$16="","n/a",IF($F$16>0,"+"&TEXT($F$16,"#,##0"),IF($F$16<0,TEXT($F$16,"#,##0"),"no change")))&")"&CHAR(10)&CHAR(10)&"Burnsville: "&TEXT($D$14,"#,##0")&" ("&IF($F$14="","n/a",IF($F$14>0,"+"&TEXT($F$14,"#,##0"),IF($F$14<0,TEXT($F$14,"#,##0"),"no change")))&")"&CHAR(10)&"Lakeville: "&TEXT($D$15,"#,##0")&" ("&IF($F$15="","n/a",IF($F$15>0,"+"&TEXT($F$15,"#,##0"),IF($F$15<0,TEXT($F$15,"#,##0"),"no change")))&")"&CHAR(10)&CHAR(10)&"Full history and charts: "&$N$5)
A54: WEEKLY LOG — one row per week, oldest first
A55: Count Date | B55: Burnsville Repair Tickets | C55: Burnsville PMs | D55: Burnsville Total | E55: Lakeville Repair Tickets | F55: Lakeville PMs | G55: Lakeville Total | H55: Repair Tickets Both Plants | I55: PMs Both Plants | J55: All Open Both Plants | K55: Change vs Previous Entry | L55: Notes
A56: =IFERROR(INDEX(Totals!$A$1:$OJ$1,MATCH(1,Totals!$A$31:$OJ$31,0)+1),"") | B56: =IFERROR(INDEX(Totals!$A$4:$OJ$4,MATCH(1,Totals!$A$31:$OJ$31,0)),"") | C56: =IFERROR(INDEX(Totals!$A$5:$OJ$5,MATCH(1,Totals!$A$31:$OJ$31,0)),"") | D56: =IF(A56="","",B56+C56) | E56: =IFERROR(INDEX(Totals!$A$9:$OJ$9,MATCH(1,Totals!$A$31:$OJ$31,0)),"") | F56: =IFERROR(INDEX(Totals!$A$10:$OJ$10,MATCH(1,Totals!$A$31:$OJ$31,0)),"") | G56: =IF(A56="","",E56+F56) | H56: =IF(A56="","",B56+E56) | I56: =IF(A56="","",C56+F56) | J56: =IF(A56="","",D56+G56) | L56: =IFERROR(IF(INDEX(Totals!$A$15:$OJ$15,MATCH(1,Totals!$A$31:$OJ$31,0)+1)=0,"",INDEX(Totals!$A$15:$OJ$15,MATCH(1,Totals!$A$31:$OJ$31,0)+1)),"")
A57: =IFERROR(INDEX(Totals!$A$1:$OJ$1,MATCH(2,Totals!$A$31:$OJ$31,0)+1),"") | B57: =IFERROR(INDEX(Totals!$A$4:$OJ$4,MATCH(2,Totals!$A$31:$OJ$31,0)),"") | C57: =IFERROR(INDEX(Totals!$A$5:$OJ$5,MATCH(2,Totals!$A$31:$OJ$31,0)),"") | D57: =IF(A57="","",B57+C57) | E57: =IFERROR(INDEX(Totals!$A$9:$OJ$9,MATCH(2,Totals!$A$31:$OJ$31,0)),"") | F57: =IFERROR(INDEX(Totals!$A$10:$OJ$10,MATCH(2,Totals!$A$31:$OJ$31,0)),"") | G57: =IF(A57="","",E57+F57) | H57: =IF(A57="","",B57+E57) | I57: =IF(A57="","",C57+F57) | J57: =IF(A57="","",D57+G57) | K57: =IF(OR(A57="",J56=""),"",J57-J56) | L57: =IFERROR(IF(INDEX(Totals!$A$15:$OJ$15,MATCH(2,Totals!$A$31:$OJ$31,0)+1)=0,"",INDEX(Totals!$A$15:$OJ$15,MATCH(2,Totals!$A$31:$OJ$31,0)+1)),"")
A58: =IFERROR(INDEX(Totals!$A$1:$OJ$1,MATCH(3,Totals!$A$31:$OJ$31,0)+1),"") | B58: =IFERROR(INDEX(Totals!$A$4:$OJ$4,MATCH(3,Totals!$A$31:$OJ$31,0)),"") | C58: =IFERROR(INDEX(Totals!$A$5:$OJ$5,MATCH(3,Totals!$A$31:$OJ$31,0)),"") | D58: =IF(A58="","",B58+C58) | E58: =IFERROR(INDEX(Totals!$A$9:$OJ$9,MATCH(3,Totals!$A$31:$OJ$31,0)),"") | F58: =IFERROR(INDEX(Totals!$A$10:$OJ$10,MATCH(3,Totals!$A$31:$OJ$31,0)),"") | G58: =IF(A58="","",E58+F58) | H58: =IF(A58="","",B58+E58) | I58: =IF(A58="","",C58+F58) | J58: =IF(A58="","",D58+G58) | K58: =IF(OR(A58="",J57=""),"",J58-J57) | L58: =IFERROR(IF(INDEX(Totals!$A$15:$OJ$15,MATCH(3,Totals!$A$31:$OJ$31,0)+1)=0,"",INDEX(Totals!$A$15:$OJ$15,MATCH(3,Totals!$A$31:$OJ$31,0)+1)),"")
A59: =IFERROR(INDEX(Totals!$A$1:$OJ$1,MATCH(4,Totals!$A$31:$OJ$31,0)+1),"") | B59: =IFERROR(INDEX(Totals!$A$4:$OJ$4,MATCH(4,Totals!$A$31:$OJ$31,0)),"") | C59: =IFERROR(INDEX(Totals!$A$5:$OJ$5,MATCH(4,Totals!$A$31:$OJ$31,0)),"") | D59: =IF(A59="","",B59+C59) | E59: =IFERROR(INDEX(Totals!$A$9:$OJ$9,MATCH(4,Totals!$A$31:$OJ$31,0)),"") | F59: =IFERROR(INDEX(Totals!$A$10:$OJ$10,MATCH(4,Totals!$A$31:$OJ$31,0)),"") | G59: =IF(A59="","",E59+F59) | H59: =IF(A59="","",B59+E59) | I59: =IF(A59="","",C59+F59) | J59: =IF(A59="","",D59+G59) | K59: =IF(OR(A59="",J58=""),"",J59-J58) | L59: =IFERROR(IF(INDEX(Totals!$A$15:$OJ$15,MATCH(4,Totals!$A$31:$OJ$31,0)+1)=0,"",INDEX(Totals!$A$15:$OJ$15,MATCH(4,Totals!$A$31:$OJ$31,0)+1)),"")
A60: =IFERROR(INDEX(Totals!$A$1:$OJ$1,MATCH(5,Totals!$A$31:$OJ$31,0)+1),"") | B60: =IFERROR(INDEX(Totals!$A$4:$OJ$4,MATCH(5,Totals!$A$31:$OJ$31,0)),"") | C60: =IFERROR(INDEX(Totals!$A$5:$OJ$5,MATCH(5,Totals!$A$31:$OJ$31,0)),"") | D60: =IF(A60="","",B60+C60) | E60: =IFERROR(INDEX(Totals!$A$9:$OJ$9,MATCH(5,Totals!$A$31:$OJ$31,0)),"") | F60: =IFERROR(INDEX(Totals!$A$10:$OJ$10,MATCH(5,Totals!$A$31:$OJ$31,0)),"") | G60: =IF(A60="","",E60+F60) | H60: =IF(A60="","",B60+E60) | I60: =IF(A60="","",C60+F60) | J60: =IF(A60="","",D60+G60) | K60: =IF(OR(A60="",J59=""),"",J60-J59) | L60: =IFERROR(IF(INDEX(Totals!$A$15:$OJ$15,MATCH(5,Totals!$A$31:$OJ$31,0)+1)=0,"",INDEX(Totals!$A$15:$OJ$15,MATCH(5,Totals!$A$31:$OJ$31,0)+1)),"")
A61: =IFERROR(INDEX(Totals!$A$1:$OJ$1,MATCH(6,Totals!$A$31:$OJ$31,0)+1),"") | B61: =IFERROR(INDEX(Totals!$A$4:$OJ$4,MATCH(6,Totals!$A$31:$OJ$31,0)),"") | C61: =IFERROR(INDEX(Totals!$A$5:$OJ$5,MATCH(6,Totals!$A$31:$OJ$31,0)),"") | D61: =IF(A61="","",B61+C61) | E61: =IFERROR(INDEX(Totals!$A$9:$OJ$9,MATCH(6,Totals!$A$31:$OJ$31,0)),"") | F61: =IFERROR(INDEX(Totals!$A$10:$OJ$10,MATCH(6,Totals!$A$31:$OJ$31,0)),"") | G61: =IF(A61="","",E61+F61) | H61: =IF(A61="","",B61+E61) | I61: =IF(A61="","",C61+F61) | J61: =IF(A61="","",D61+G61) | K61: =IF(OR(A61="",J60=""),"",J61-J60) | L61: =IFERROR(IF(INDEX(Totals!$A$15:$OJ$15,MATCH(6,Totals!$A$31:$OJ$31,0)+1)=0,"",INDEX(Totals!$A$15:$OJ$15,MATCH(6,Totals!$A$31:$OJ$31,0)+1)),"")
A62: =IFERROR(INDEX(Totals!$A$1:$OJ$1,MATCH(7,Totals!$A$31:$OJ$31,0)+1),"") | B62: =IFERROR(INDEX(Totals!$A$4:$OJ$4,MATCH(7,Totals!$A$31:$OJ$31,0)),"") | C62: =IFERROR(INDEX(Totals!$A$5:$OJ$5,MATCH(7,Totals!$A$31:$OJ$31,0)),"") | D62: =IF(A62="","",B62+C62) | E62: =IFERROR(INDEX(Totals!$A$9:$OJ$9,MATCH(7,Totals!$A$31:$OJ$31,0)),"") | F62: =IFERROR(INDEX(Totals!$A$10:$OJ$10,MATCH(7,Totals!$A$31:$OJ$31,0)),"") | G62: =IF(A62="","",E62+F62) | H62: =IF(A62="","",B62+E62) | I62: =IF(A62="","",C62+F62) | J62: =IF(A62="","",D62+G62) | K62: =IF(OR(A62="",J61=""),"",J62-J61) | L62: =IFERROR(IF(INDEX(Totals!$A$15:$OJ$15,MATCH(7,Totals!$A$31:$OJ$31,0)+1)=0,"",INDEX(Totals!$A$15:$OJ$15,MATCH(7,Totals!$A$31:$OJ$31,0)+1)),"")
A63: =IFERROR(INDEX(Totals!$A$1:$OJ$1,MATCH(8,Totals!$A$31:$OJ$31,0)+1),"") | B63: =IFERROR(INDEX(Totals!$A$4:$OJ$4,MATCH(8,Totals!$A$31:$OJ$31,0)),"") | C63: =IFERROR(INDEX(Totals!$A$5:$OJ$5,MATCH(8,Totals!$A$31:$OJ$31,0)),"") | D63: =IF(A63="","",B63+C63) | E63: =IFERROR(INDEX(Totals!$A$9:$OJ$9,MATCH(8,Totals!$A$31:$OJ$31,0)),"") | F63: =IFERROR(INDEX(Totals!$A$10:$OJ$10,MATCH(8,Totals!$A$31:$OJ$31,0)),"") | G63: =IF(A63="","",E63+F63) | H63: =IF(A63="","",B63+E63) | I63: =IF(A63="","",C63+F63) | J63: =IF(A63="","",D63+G63) | K63: =IF(OR(A63="",J62=""),"",J63-J62) | L63: =IFERROR(IF(INDEX(Totals!$A$15:$OJ$15,MATCH(8,Totals!$A$31:$OJ$31,0)+1)=0,"",INDEX(Totals!$A$15:$OJ$15,MATCH(8,Totals!$A$31:$OJ$31,0)+1)),"")
A64: =IFERROR(INDEX(Totals!$A$1:$OJ$1,MATCH(9,Totals!$A$31:$OJ$31,0)+1),"") | B64: =IFERROR(INDEX(Totals!$A$4:$OJ$4,MATCH(9,Totals!$A$31:$OJ$31,0)),"") | C64: =IFERROR(INDEX(Totals!$A$5:$OJ$5,MATCH(9,Totals!$A$31:$OJ$31,0)),"") | D64: =IF(A64="","",B64+C64) | E64: =IFERROR(INDEX(Totals!$A$9:$OJ$9,MATCH(9,Totals!$A$31:$OJ$31,0)),"") | F64: =IFERROR(INDEX(Totals!$A$10:$OJ$10,MATCH(9,Totals!$A$31:$OJ$31,0)),"") | G64: =IF(A64="","",E64+F64) | H64: =IF(A64="","",B64+E64) | I64: =IF(A64="","",C64+F64) | J64: =IF(A64="","",D64+G64) | K64: =IF(OR(A64="",J63=""),"",J64-J63) | L64: =IFERROR(IF(INDEX(Totals!$A$15:$OJ$15,MATCH(9,Totals!$A$31:$OJ$31,0)+1)=0,"",INDEX(Totals!$A$15:$OJ$15,MATCH(9,Totals!$A$31:$OJ$31,0)+1)),"")
A65: =IFERROR(INDEX(Totals!$A$1:$OJ$1,MATCH(10,Totals!$A$31:$OJ$31,0)+1),"") | B65: =IFERROR(INDEX(Totals!$A$4:$OJ$4,MATCH(10,Totals!$A$31:$OJ$31,0)),"") | C65: =IFERROR(INDEX(Totals!$A$5:$OJ$5,MATCH(10,Totals!$A$31:$OJ$31,0)),"") | D65: =IF(A65="","",B65+C65) | E65: =IFERROR(INDEX(Totals!$A$9:$OJ$9,MATCH(10,Totals!$A$31:$OJ$31,0)),"") | F65: =IFERROR(INDEX(Totals!$A$10:$OJ$10,MATCH(10,Totals!$A$31:$OJ$31,0)),"") | G65: =IF(A65="","",E65+F65) | H65: =IF(A65="","",B65+E65) | I65: =IF(A65="","",C65+F65) | J65: =IF(A65="","",D65+G65) | K65: =IF(OR(A65="",J64=""),"",J65-J64) | L65: =IFERROR(IF(INDEX(Totals!$A$15:$OJ$15,MATCH(10,Totals!$A$31:$OJ$31,0)+1)=0,"",INDEX(Totals!$A$15:$OJ$15,MATCH(10,Totals!$A$31:$OJ$31,0)+1)),"")
A66: =IFERROR(INDEX(Totals!$A$1:$OJ$1,MATCH(11,Totals!$A$31:$OJ$31,0)+1),"") | B66: =IFERROR(INDEX(Totals!$A$4:$OJ$4,MATCH(11,Totals!$A$31:$OJ$31,0)),"") | C66: =IFERROR(INDEX(Totals!$A$5:$OJ$5,MATCH(11,Totals!$A$31:$OJ$31,0)),"") | D66: =IF(A66="","",B66+C66) | E66: =IFERROR(INDEX(Totals!$A$9:$OJ$9,MATCH(11,Totals!$A$31:$OJ$31,0)),"") | F66: =IFERROR(INDEX(Totals!$A$10:$OJ$10,MATCH(11,Totals!$A$31:$OJ$31,0)),"") | G66: =IF(A66="","",E66+F66) | H66: =IF(A66="","",B66+E66) | I66: =IF(A66="","",C66+F66) | J66: =IF(A66="","",D66+G66) | K66: =IF(OR(A66="",J65=""),"",J66-J65) | L66: =IFERROR(IF(INDEX(Totals!$A$15:$OJ$15,MATCH(11,Totals!$A$31:$OJ$31,0)+1)=0,"",INDEX(Totals!$A$15:$OJ$15,MATCH(11,Totals!$A$31:$OJ$31,0)+1)),"")
A67: =IFERROR(INDEX(Totals!$A$1:$OJ$1,MATCH(12,Totals!$A$31:$OJ$31,0)+1),"") | B67: =IFERROR(INDEX(Totals!$A$4:$OJ$4,MATCH(12,Totals!$A$31:$OJ$31,0)),"") | C67: =IFERROR(INDEX(Totals!$A$5:$OJ$5,MATCH(12,Totals!$A$31:$OJ$31,0)),"") | D67: =IF(A67="","",B67+C67) | E67: =IFERROR(INDEX(Totals!$A$9:$OJ$9,MATCH(12,Totals!$A$31:$OJ$31,0)),"") | F67: =IFERROR(INDEX(Totals!$A$10:$OJ$10,MATCH(12,Totals!$A$31:$OJ$31,0)),"") | G67: =IF(A67="","",E67+F67) | H67: =IF(A67="","",B67+E67) | I67: =IF(A67="","",C67+F67) | J67: =IF(A67="","",D67+G67) | K67: =IF(OR(A67="",J66=""),"",J67-J66) | L67: =IFERROR(IF(INDEX(Totals!$A$15:$OJ$15,MATCH(12,Totals!$A$31:$OJ$31,0)+1)=0,"",INDEX(Totals!$A$15:$OJ$15,MATCH(12,Totals!$A$31:$OJ$31,0)+1)),"")
A68: =IFERROR(INDEX(Totals!$A$1:$OJ$1,MATCH(13,Totals!$A$31:$OJ$31,0)+1),"") | B68: =IFERROR(INDEX(Totals!$A$4:$OJ$4,MATCH(13,Totals!$A$31:$OJ$31,0)),"") | C68: =IFERROR(INDEX(Totals!$A$5:$OJ$5,MATCH(13,Totals!$A$31:$OJ$31,0)),"") | D68: =IF(A68="","",B68+C68) | E68: =IFERROR(INDEX(Totals!$A$9:$OJ$9,MATCH(13,Totals!$A$31:$OJ$31,0)),"") | F68: =IFERROR(INDEX(Totals!$A$10:$OJ$10,MATCH(13,Totals!$A$31:$OJ$31,0)),"") | G68: =IF(A68="","",E68+F68) | H68: =IF(A68="","",B68+E68) | I68: =IF(A68="","",C68+F68) | J68: =IF(A68="","",D68+G68) | K68: =IF(OR(A68="",J67=""),"",J68-J67) | L68: =IFERROR(IF(INDEX(Totals!$A$15:$OJ$15,MATCH(13,Totals!$A$31:$OJ$31,0)+1)=0,"",INDEX(Totals!$A$15:$OJ$15,MATCH(13,Totals!$A$31:$OJ$31,0)+1)),"")
A69: =IFERROR(INDEX(Totals!$A$1:$OJ$1,MATCH(14,Totals!$A$31:$OJ$31,0)+1),"") | B69: =IFERROR(INDEX(Totals!$A$4:$OJ$4,MATCH(14,Totals!$A$31:$OJ$31,0)),"") | C69: =IFERROR(INDEX(Totals!$A$5:$OJ$5,MATCH(14,Totals!$A$31:$OJ$31,0)),"") | D69: =IF(A69="","",B69+C69) | E69: =IFERROR(INDEX(Totals!$A$9:$OJ$9,MATCH(14,Totals!$A$31:$OJ$31,0)),"") | F69: =IFERROR(INDEX(Totals!$A$10:$OJ$10,MATCH(14,Totals!$A$31:$OJ$31,0)),"") | G69: =IF(A69="","",E69+F69) | H69: =IF(A69="","",B69+E69) | I69: =IF(A69="","",C69+F69) | J69: =IF(A69="","",D69+G69) | K69: =IF(OR(A69="",J68=""),"",J69-J68) | L69: =IFERROR(IF(INDEX(Totals!$A$15:$OJ$15,MATCH(14,Totals!$A$31:$OJ$31,0)+1)=0,"",INDEX(Totals!$A$15:$OJ$15,MATCH(14,Totals!$A$31:$OJ$31,0)+1)),"")
A70: =IFERROR(INDEX(Totals!$A$1:$OJ$1,MATCH(15,Totals!$A$31:$OJ$31,0)+1),"") | B70: =IFERROR(INDEX(Totals!$A$4:$OJ$4,MATCH(15,Totals!$A$31:$OJ$31,0)),"") | C70: =IFERROR(INDEX(Totals!$A$5:$OJ$5,MATCH(15,Totals!$A$31:$OJ$31,0)),"") | D70: =IF(A70="","",B70+C70) | E70: =IFERROR(INDEX(Totals!$A$9:$OJ$9,MATCH(15,Totals!$A$31:$OJ$31,0)),"") | F70: =IFERROR(INDEX(Totals!$A$10:$OJ$10,MATCH(15,Totals!$A$31:$OJ$31,0)),"") | G70: =IF(A70="","",E70+F70) | H70: =IF(A70="","",B70+E70) | I70: =IF(A70="","",C70+F70) | J70: =IF(A70="","",D70+G70) | K70: =IF(OR(A70="",J69=""),"",J70-J69) | L70: =IFERROR(IF(INDEX(Totals!$A$15:$OJ$15,MATCH(15,Totals!$A$31:$OJ$31,0)+1)=0,"",INDEX(Totals!$A$15:$OJ$15,MATCH(15,Totals!$A$31:$OJ$31,0)+1)),"")
A71: =IFERROR(INDEX(Totals!$A$1:$OJ$1,MATCH(16,Totals!$A$31:$OJ$31,0)+1),"") | B71: =IFERROR(INDEX(Totals!$A$4:$OJ$4,MATCH(16,Totals!$A$31:$OJ$31,0)),"") | C71: =IFERROR(INDEX(Totals!$A$5:$OJ$5,MATCH(16,Totals!$A$31:$OJ$31,0)),"") | D71: =IF(A71="","",B71+C71) | E71: =IFERROR(INDEX(Totals!$A$9:$OJ$9,MATCH(16,Totals!$A$31:$OJ$31,0)),"") | F71: =IFERROR(INDEX(Totals!$A$10:$OJ$10,MATCH(16,Totals!$A$31:$OJ$31,0)),"") | G71: =IF(A71="","",E71+F71) | H71: =IF(A71="","",B71+E71) | I71: =IF(A71="","",C71+F71) | J71: =IF(A71="","",D71+G71) | K71: =IF(OR(A71="",J70=""),"",J71-J70) | L71: =IFERROR(IF(INDEX(Totals!$A$15:$OJ$15,MATCH(16,Totals!$A$31:$OJ$31,0)+1)=0,"",INDEX(Totals!$A$15:$OJ$15,MATCH(16,Totals!$A$31:$OJ$31,0)+1)),"")
A72: =IFERROR(INDEX(Totals!$A$1:$OJ$1,MATCH(17,Totals!$A$31:$OJ$31,0)+1),"") | B72: =IFERROR(INDEX(Totals!$A$4:$OJ$4,MATCH(17,Totals!$A$31:$OJ$31,0)),"") | C72: =IFERROR(INDEX(Totals!$A$5:$OJ$5,MATCH(17,Totals!$A$31:$OJ$31,0)),"") | D72: =IF(A72="","",B72+C72) | E72: =IFERROR(INDEX(Totals!$A$9:$OJ$9,MATCH(17,Totals!$A$31:$OJ$31,0)),"") | F72: =IFERROR(INDEX(Totals!$A$10:$OJ$10,MATCH(17,Totals!$A$31:$OJ$31,0)),"") | G72: =IF(A72="","",E72+F72) | H72: =IF(A72="","",B72+E72) | I72: =IF(A72="","",C72+F72) | J72: =IF(A72="","",D72+G72) | K72: =IF(OR(A72="",J71=""),"",J72-J71) | L72: =IFERROR(IF(INDEX(Totals!$A$15:$OJ$15,MATCH(17,Totals!$A$31:$OJ$31,0)+1)=0,"",INDEX(Totals!$A$15:$OJ$15,MATCH(17,Totals!$A$31:$OJ$31,0)+1)),"")
A73: =IFERROR(INDEX(Totals!$A$1:$OJ$1,MATCH(18,Totals!$A$31:$OJ$31,0)+1),"") | B73: =IFERROR(INDEX(Totals!$A$4:$OJ$4,MATCH(18,Totals!$A$31:$OJ$31,0)),"") | C73: =IFERROR(INDEX(Totals!$A$5:$OJ$5,MATCH(18,Totals!$A$31:$OJ$31,0)),"") | D73: =IF(A73="","",B73+C73) | E73: =IFERROR(INDEX(Totals!$A$9:$OJ$9,MATCH(18,Totals!$A$31:$OJ$31,0)),"") | F73: =IFERROR(INDEX(Totals!$A$10:$OJ$10,MATCH(18,Totals!$A$31:$OJ$31,0)),"") | G73: =IF(A73="","",E73+F73) | H73: =IF(A73="","",B73+E73) | I73: =IF(A73="","",C73+F73) | J73: =IF(A73="","",D73+G73) | K73: =IF(OR(A73="",J72=""),"",J73-J72) | L73: =IFERROR(IF(INDEX(Totals!$A$15:$OJ$15,MATCH(18,Totals!$A$31:$OJ$31,0)+1)=0,"",INDEX(Totals!$A$15:$OJ$15,MATCH(18,Totals!$A$31:$OJ$31,0)+1)),"")
A74: =IFERROR(INDEX(Totals!$A$1:$OJ$1,MATCH(19,Totals!$A$31:$OJ$31,0)+1),"") | B74: =IFERROR(INDEX(Totals!$A$4:$OJ$4,MATCH(19,Totals!$A$31:$OJ$31,0)),"") | C74: =IFERROR(INDEX(Totals!$A$5:$OJ$5,MATCH(19,Totals!$A$31:$OJ$31,0)),"") | D74: =IF(A74="","",B74+C74) | E74: =IFERROR(INDEX(Totals!$A$9:$OJ$9,MATCH(19,Totals!$A$31:$OJ$31,0)),"") | F74: =IFERROR(INDEX(Totals!$A$10:$OJ$10,MATCH(19,Totals!$A$31:$OJ$31,0)),"") | G74: =IF(A74="","",E74+F74) | H74: =IF(A74="","",B74+E74) | I74: =IF(A74="","",C74+F74) | J74: =IF(A74="","",D74+G74) | K74: =IF(OR(A74="",J73=""),"",J74-J73) | L74: =IFERROR(IF(INDEX(Totals!$A$15:$OJ$15,MATCH(19,Totals!$A$31:$OJ$31,0)+1)=0,"",INDEX(Totals!$A$15:$OJ$15,MATCH(19,Totals!$A$31:$OJ$31,0)+1)),"")
...

Sheet Totals
A1: DATE | B1: 46280 | D1: DATE | E1: 46286 | G1: DATE | H1: 46293 | J1: DATE | K1: 46300 | M1: DATE | N1: 46307 | P1: DATE | Q1: 46314 | S1: DATE | T1: 46321 | V1: DATE | W1: 46328 | Y1: DATE | Z1: 46335 | AB1: DATE | AC1: 46342 | AE1: DATE | AF1: 46349 | AH1: DATE | AI1: 46356 | AK1: DATE | AL1: 46363 | AN1: DATE | AO1: 46370 | AQ1: DATE | AR1: 46377 | AT1: DATE | AU1: 46384 | AW1: DATE | AX1: 46391 | AZ1: DATE | BA1: 46398 | BC1: DATE | BD1: 46405 | BF1: DATE | BG1: 46412 | BI1: DATE | BJ1: 46419 | BL1: DATE | BM1: 46426 | BO1: DATE | BP1: 46433 | BR1: DATE | BS1: 46440 | BU1: DATE | BV1: 46447 | BX1: DATE | BY1: 46454 | CA1: DATE | CB1: 46461 | CD1: DATE | CE1: 46468 | CG1: DATE | CH1: 46475 | CJ1: DATE | CK1: 46482 | CM1: DATE | CN1: 46489 | CP1: DATE | CQ1: 46496 | CS1: DATE | CT1: 46503 | CV1: DATE | CW1: 46510 | CY1: DATE | CZ1: 46517 | DB1: DATE | DC1: 46524 | DE1: DATE | DF1: 46531 | DH1: DATE | DI1: 46538 | DK1: DATE | DL1: 46545 | DN1: DATE | DO1: 46552 | DQ1: DATE | DR1: 46559 | DT1: DATE | DU1: 46566 | DW1: DATE | DX1: 46573 | DZ1: DATE | EA1: 46580 | EC1: DATE | ED1: 46587 | EF1: DATE | EG1: 46594 | EI1: DATE | EJ1: 46601 | EL1: DATE | EM1: 46608 | EO1: DATE | EP1: 46615 | ER1: DATE | ES1: 46622 | EU1: DATE | EV1: 46629 | EX1: DATE | EY1: 46636 | FA1: DATE | FB1: 46643 | FD1: DATE | FE1: 46650 | FG1: DATE | FH1: 46657 | FJ1: DATE | FK1: 46664 | FM1: DATE | FN1: 46671 | FP1: DATE | FQ1: 46678 | FS1: DATE | FT1: 46685 | FV1: DATE | FW1: 46692 | FY1: DATE | FZ1: 46699 | GB1: DATE | GC1: 46706 | GE1: DATE | GF1: 46713 | GH1: DATE | GI1: 46720 | GK1: DATE | GL1: 46727 | GN1: DATE | GO1: 46734 | GQ1: DATE | GR1: 46741 | GT1: DATE | GU1: 46748 | GW1: DATE | GX1: 46755 | GZ1: DATE | HA1: 46762 | HC1: DATE | HD1: 46769 | HF1: DATE | HG1: 46776 | HI1: DATE | HJ1: 46783 | HL1: DATE | HM1: 46790 | HO1: DATE | HP1: 46797 | HR1: DATE | HS1: 46804 | HU1: DATE | HV1: 46811 | HX1: DATE | HY1: 46818 | IA1: DATE | IB1: 46825 | ID1: DATE | IE1: 46832 | IG1: DATE | IH1: 46839 | IJ1: DATE | IK1: 46846 | IM1: DATE | IN1: 46853 | IP1: DATE | IQ1: 46860 | IS1: DATE | IT1: 46867 | IV1: DATE | IW1: 46874 | IY1: DATE | IZ1: 46881 | JB1: DATE | JC1: 46888 | JE1: DATE | JF1: 46895 | JH1: DATE | JI1: 46902 | JK1: DATE | JL1: 46909 | JN1: DATE | JO1: 46916 | JQ1: DATE | JR1: 46923 | JT1: DATE | JU1: 46930 | JW1: DATE | JX1: 46937 | JZ1: DATE | KA1: 46944 | KC1: DATE | KD1: 46951 | KF1: DATE | KG1: 46958 | KI1: DATE | KJ1: 46965 | KL1: DATE | KM1: 46972 | KO1: DATE | KP1: 46979 | KR1: DATE | KS1: 46986 | KU1: DATE | KV1: 46993 | KX1: DATE | KY1: 47000 | LA1: DATE | LB1: 47007
A3: BURNSVILLE | D3: BURNSVILLE | G3: BURNSVILLE | J3: BURNSVILLE | M3: BURNSVILLE | P3: BURNSVILLE | S3: BURNSVILLE | V3: BURNSVILLE | Y3: BURNSVILLE | AB3: BURNSVILLE | AE3: BURNSVILLE | AH3: BURNSVILLE | AK3: BURNSVILLE | AN3: BURNSVILLE | AQ3: BURNSVILLE | AT3: BURNSVILLE | AW3: BURNSVILLE | AZ3: BURNSVILLE | BC3: BURNSVILLE | BF3: BURNSVILLE | BI3: BURNSVILLE | BL3: BURNSVILLE | BO3: BURNSVILLE | BR3: BURNSVILLE | BU3: BURNSVILLE | BX3: BURNSVILLE | CA3: BURNSVILLE | CD3: BURNSVILLE | CG3: BURNSVILLE | CJ3: BURNSVILLE | CM3: BURNSVILLE | CP3: BURNSVILLE | CS3: BURNSVILLE | CV3: BURNSVILLE | CY3: BURNSVILLE | DB3: BURNSVILLE | DE3: BURNSVILLE | DH3: BURNSVILLE | DK3: BURNSVILLE | DN3: BURNSVILLE | DQ3: BURNSVILLE | DT3: BURNSVILLE | DW3: BURNSVILLE | DZ3: BURNSVILLE | EC3: BURNSVILLE | EF3: BURNSVILLE | EI3: BURNSVILLE | EL3: BURNSVILLE | EO3: BURNSVILLE | ER3: BURNSVILLE | EU3: BURNSVILLE | EX3: BURNSVILLE | FA3: BURNSVILLE | FD3: BURNSVILLE | FG3: BURNSVILLE | FJ3: BURNSVILLE | FM3: BURNSVILLE | FP3: BURNSVILLE | FS3: BURNSVILLE | FV3: BURNSVILLE | FY3: BURNSVILLE | GB3: BURNSVILLE | GE3: BURNSVILLE | GH3: BURNSVILLE | GK3: BURNSVILLE | GN3: BURNSVILLE | GQ3: BURNSVILLE | GT3: BURNSVILLE | GW3: BURNSVILLE | GZ3: BURNSVILLE | HC3: BURNSVILLE | HF3: BURNSVILLE | HI3: BURNSVILLE | HL3: BURNSVILLE | HO3: BURNSVILLE | HR3: BURNSVILLE | HU3: BURNSVILLE | HX3: BURNSVILLE | IA3: BURNSVILLE | ID3: BURNSVILLE | IG3: BURNSVILLE | IJ3: BURNSVILLE | IM3: BURNSVILLE | IP3: BURNSVILLE | IS3: BURNSVILLE | IV3: BURNSVILLE | IY3: BURNSVILLE | JB3: BURNSVILLE | JE3: BURNSVILLE | JH3: BURNSVILLE | JK3: BURNSVILLE | JN3: BURNSVILLE | JQ3: BURNSVILLE | JT3: BURNSVILLE | JW3: BURNSVILLE | JZ3: BURNSVILLE | KC3: BURNSVILLE | KF3: BURNSVILLE | KI3: BURNSVILLE | KL3: BURNSVILLE | KO3: BURNSVILLE | KR3: BURNSVILLE | KU3: BURNSVILLE | KX3: BURNSVILLE | LA3: BURNSVILLE
A4: 11 | B4: OPEN REPAIR TICKETS | D4: 7 | E4: OPEN REPAIR TICKETS | H4: OPEN REPAIR TICKETS | K4: OPEN REPAIR TICKETS | N4: OPEN REPAIR TICKETS | Q4: OPEN REPAIR TICKETS | T4: OPEN REPAIR TICKETS | W4: OPEN REPAIR TICKETS | Z4: OPEN REPAIR TICKETS | AC4: OPEN REPAIR TICKETS | AF4: OPEN REPAIR TICKETS | AI4: OPEN REPAIR TICKETS | AL4: OPEN REPAIR TICKETS | AO4: OPEN REPAIR TICKETS | AR4: OPEN REPAIR TICKETS | AU4: OPEN REPAIR TICKETS | AX4: OPEN REPAIR TICKETS | BA4: OPEN REPAIR TICKETS | BD4: OPEN REPAIR TICKETS | BG4: OPEN REPAIR TICKETS | BJ4: OPEN REPAIR TICKETS | BM4: OPEN REPAIR TICKETS | BP4: OPEN REPAIR TICKETS | BS4: OPEN REPAIR TICKETS | BV4: OPEN REPAIR TICKETS | BY4: OPEN REPAIR TICKETS | CB4: OPEN REPAIR TICKETS | CE4: OPEN REPAIR TICKETS | CH4: OPEN REPAIR TICKETS | CK4: OPEN REPAIR TICKETS | CN4: OPEN REPAIR TICKETS | CQ4: OPEN REPAIR TICKETS | CT4: OPEN REPAIR TICKETS | CW4: OPEN REPAIR TICKETS | CZ4: OPEN REPAIR TICKETS | DC4: OPEN REPAIR TICKETS | DF4: OPEN REPAIR TICKETS | DI4: OPEN REPAIR TICKETS | DL4: OPEN REPAIR TICKETS | DO4: OPEN REPAIR TICKETS | DR4: OPEN REPAIR TICKETS | DU4: OPEN REPAIR TICKETS | DX4: OPEN REPAIR TICKETS | EA4: OPEN REPAIR TICKETS | ED4: OPEN REPAIR TICKETS | EG4: OPEN REPAIR TICKETS | EJ4: OPEN REPAIR TICKETS | EM4: OPEN REPAIR TICKETS | EP4: OPEN REPAIR TICKETS | ES4: OPEN REPAIR TICKETS | EV4: OPEN REPAIR TICKETS | EY4: OPEN REPAIR TICKETS | FB4: OPEN REPAIR TICKETS | FE4: OPEN REPAIR TICKETS | FH4: OPEN REPAIR TICKETS | FK4: OPEN REPAIR TICKETS | FN4: OPEN REPAIR TICKETS | FQ4: OPEN REPAIR TICKETS | FT4: OPEN REPAIR TICKETS | FW4: OPEN REPAIR TICKETS | FZ4: OPEN REPAIR TICKETS | GC4: OPEN REPAIR TICKETS | GF4: OPEN REPAIR TICKETS | GI4: OPEN REPAIR TICKETS | GL4: OPEN REPAIR TICKETS | GO4: OPEN REPAIR TICKETS | GR4: OPEN REPAIR TICKETS | GU4: OPEN REPAIR TICKETS | GX4: OPEN REPAIR TICKETS | HA4: OPEN REPAIR TICKETS | HD4: OPEN REPAIR TICKETS | HG4: OPEN REPAIR TICKETS | HJ4: OPEN REPAIR TICKETS | HM4: OPEN REPAIR TICKETS | HP4: OPEN REPAIR TICKETS | HS4: OPEN REPAIR TICKETS | HV4: OPEN REPAIR TICKETS | HY4: OPEN REPAIR TICKETS | IB4: OPEN REPAIR TICKETS | IE4: OPEN REPAIR TICKETS | IH4: OPEN REPAIR TICKETS | IK4: OPEN REPAIR TICKETS | IN4: OPEN REPAIR TICKETS | IQ4: OPEN REPAIR TICKETS | IT4: OPEN REPAIR TICKETS | IW4: OPEN REPAIR TICKETS | IZ4: OPEN REPAIR TICKETS | JC4: OPEN REPAIR TICKETS | JF4: OPEN REPAIR TICKETS | JI4: OPEN REPAIR TICKETS | JL4: OPEN REPAIR TICKETS | JO4: OPEN REPAIR TICKETS | JR4: OPEN REPAIR TICKETS | JU4: OPEN REPAIR TICKETS | JX4: OPEN REPAIR TICKETS | KA4: OPEN REPAIR TICKETS | KD4: OPEN REPAIR TICKETS | KG4: OPEN REPAIR TICKETS | KJ4: OPEN REPAIR TICKETS | KM4: OPEN REPAIR TICKETS | KP4: OPEN REPAIR TICKETS | KS4: OPEN REPAIR TICKETS | KV4: OPEN REPAIR TICKETS | KY4: OPEN REPAIR TICKETS | LB4: OPEN REPAIR TICKETS
A5: 3 | B5: OPEN PMS | D5: 6 | E5: OPEN PMS | H5: OPEN PMS | K5: OPEN PMS | N5: OPEN PMS | Q5: OPEN PMS | T5: OPEN PMS | W5: OPEN PMS | Z5: OPEN PMS | AC5: OPEN PMS | AF5: OPEN PMS | AI5: OPEN PMS | AL5: OPEN PMS | AO5: OPEN PMS | AR5: OPEN PMS | AU5: OPEN PMS | AX5: OPEN PMS | BA5: OPEN PMS | BD5: OPEN PMS | BG5: OPEN PMS | BJ5: OPEN PMS | BM5: OPEN PMS | BP5: OPEN PMS | BS5: OPEN PMS | BV5: OPEN PMS | BY5: OPEN PMS | CB5: OPEN PMS | CE5: OPEN PMS | CH5: OPEN PMS | CK5: OPEN PMS | CN5: OPEN PMS | CQ5: OPEN PMS | CT5: OPEN PMS | CW5: OPEN PMS | CZ5: OPEN PMS | DC5: OPEN PMS | DF5: OPEN PMS | DI5: OPEN PMS | DL5: OPEN PMS | DO5: OPEN PMS | DR5: OPEN PMS | DU5: OPEN PMS | DX5: OPEN PMS | EA5: OPEN PMS | ED5: OPEN PMS | EG5: OPEN PMS | EJ5: OPEN PMS | EM5: OPEN PMS | EP5: OPEN PMS | ES5: OPEN PMS | EV5: OPEN PMS | EY5: OPEN PMS | FB5: OPEN PMS | FE5: OPEN PMS | FH5: OPEN PMS | FK5: OPEN PMS | FN5: OPEN PMS | FQ5: OPEN PMS | FT5: OPEN PMS | FW5: OPEN PMS | FZ5: OPEN PMS | GC5: OPEN PMS | GF5: OPEN PMS | GI5: OPEN PMS | GL5: OPEN PMS | GO5: OPEN PMS | GR5: OPEN PMS | GU5: OPEN PMS | GX5: OPEN PMS | HA5: OPEN PMS | HD5: OPEN PMS | HG5: OPEN PMS | HJ5: OPEN PMS | HM5: OPEN PMS | HP5: OPEN PMS | HS5: OPEN PMS | HV5: OPEN PMS | HY5: OPEN PMS | IB5: OPEN PMS | IE5: OPEN PMS | IH5: OPEN PMS | IK5: OPEN PMS | IN5: OPEN PMS | IQ5: OPEN PMS | IT5: OPEN PMS | IW5: OPEN PMS | IZ5: OPEN PMS | JC5: OPEN PMS | JF5: OPEN PMS | JI5: OPEN PMS | JL5: OPEN PMS | JO5: OPEN PMS | JR5: OPEN PMS | JU5: OPEN PMS | JX5: OPEN PMS | KA5: OPEN PMS | KD5: OPEN PMS | KG5: OPEN PMS | KJ5: OPEN PMS | KM5: OPEN PMS | KP5: OPEN PMS | KS5: OPEN PMS | KV5: OPEN PMS | KY5: OPEN PMS | LB5: OPEN PMS
A6: =SUM(A4+A5) | B6: TOTAL | D6: =SUM(D4+D5) | E6: TOTAL | G6: =SUM(G4+G5) | H6: TOTAL | J6: =SUM(J4+J5) | K6: TOTAL | M6: =SUM(M4+M5) | N6: TOTAL | P6: =SUM(P4+P5) | Q6: TOTAL | S6: =SUM(S4+S5) | T6: TOTAL | V6: =SUM(V4+V5) | W6: TOTAL | Y6: =SUM(Y4+Y5) | Z6: TOTAL | AB6: =SUM(AB4+AB5) | AC6: TOTAL | AE6: =SUM(AE4+AE5) | AF6: TOTAL | AH6: =SUM(AH4+AH5) | AI6: TOTAL | AK6: =SUM(AK4+AK5) | AL6: TOTAL | AN6: =SUM(AN4+AN5) | AO6: TOTAL | AQ6: =SUM(AQ4+AQ5) | AR6: TOTAL | AT6: =SUM(AT4+AT5) | AU6: TOTAL | AW6: =SUM(AW4+AW5) | AX6: TOTAL | AZ6: =SUM(AZ4+AZ5) | BA6: TOTAL | BC6: =SUM(BC4+BC5) | BD6: TOTAL | BF6: =SUM(BF4+BF5) | BG6: TOTAL | BI6: =SUM(BI4+BI5) | BJ6: TOTAL | BL6: =SUM(BL4+BL5) | BM6: TOTAL | BO6: =SUM(BO4+BO5) | BP6: TOTAL | BR6: =SUM(BR4+BR5) | BS6: TOTAL | BU6: =SUM(BU4+BU5) | BV6: TOTAL | BX6: =SUM(BX4+BX5) | BY6: TOTAL | CA6: =SUM(CA4+CA5) | CB6: TOTAL | CD6: =SUM(CD4+CD5) | CE6: TOTAL | CG6: =SUM(CG4+CG5) | CH6: TOTAL | CJ6: =SUM(CJ4+CJ5) | CK6: TOTAL | CM6: =SUM(CM4+CM5) | CN6: TOTAL | CP6: =SUM(CP4+CP5) | CQ6: TOTAL | CS6: =SUM(CS4+CS5) | CT6: TOTAL | CV6: =SUM(CV4+CV5) | CW6: TOTAL | CY6: =SUM(CY4+CY5) | CZ6: TOTAL | DB6: =SUM(DB4+DB5) | DC6: TOTAL | DE6: =SUM(DE4+DE5) | DF6: TOTAL | DH6: =SUM(DH4+DH5) | DI6: TOTAL | DK6: =SUM(DK4+DK5) | DL6: TOTAL | DN6: =SUM(DN4+DN5) | DO6: TOTAL | DQ6: =SUM(DQ4+DQ5) | DR6: TOTAL | DT6: =SUM(DT4+DT5) | DU6: TOTAL | DW6: =SUM(DW4+DW5) | DX6: TOTAL | DZ6: =SUM(DZ4+DZ5) | EA6: TOTAL | EC6: =SUM(EC4+EC5) | ED6: TOTAL | EF6: =SUM(EF4+EF5) | EG6: TOTAL | EI6: =SUM(EI4+EI5) | EJ6: TOTAL | EL6: =SUM(EL4+EL5) | EM6: TOTAL | EO6: =SUM(EO4+EO5) | EP6: TOTAL | ER6: =SUM(ER4+ER5) | ES6: TOTAL | EU6: =SUM(EU4+EU5) | EV6: TOTAL | EX6: =SUM(EX4+EX5) | EY6: TOTAL | FA6: =SUM(FA4+FA5) | FB6: TOTAL | FD6: =SUM(FD4+FD5) | FE6: TOTAL | FG6: =SUM(FG4+FG5) | FH6: TOTAL | FJ6: =SUM(FJ4+FJ5) | FK6: TOTAL | FM6: =SUM(FM4+FM5) | FN6: TOTAL | FP6: =SUM(FP4+FP5) | FQ6: TOTAL | FS6: =SUM(FS4+FS5) | FT6: TOTAL | FV6: =SUM(FV4+FV5) | FW6: TOTAL | FY6: =SUM(FY4+FY5) | FZ6: TOTAL | GB6: =SUM(GB4+GB5) | GC6: TOTAL | GE6: =SUM(GE4+GE5) | GF6: TOTAL | GH6: =SUM(GH4+GH5) | GI6: TOTAL | GK6: =SUM(GK4+GK5) | GL6: TOTAL | GN6: =SUM(GN4+GN5) | GO6: TOTAL | GQ6: =SUM(GQ4+GQ5) | GR6: TOTAL | GT6: =SUM(GT4+GT5) | GU6: TOTAL | GW6: =SUM(GW4+GW5) | GX6: TOTAL | GZ6: =SUM(GZ4+GZ5) | HA6: TOTAL | HC6: =SUM(HC4+HC5) | HD6: TOTAL | HF6: =SUM(HF4+HF5) | HG6: TOTAL | HI6: =SUM(HI4+HI5) | HJ6: TOTAL | HL6: =SUM(HL4+HL5) | HM6: TOTAL | HO6: =SUM(HO4+HO5) | HP6: TOTAL | HR6: =SUM(HR4+HR5) | HS6: TOTAL | HU6: =SUM(HU4+HU5) | HV6: TOTAL | HX6: =SUM(HX4+HX5) | HY6: TOTAL | IA6: =SUM(IA4+IA5) | IB6: TOTAL | ID6: =SUM(ID4+ID5) | IE6: TOTAL | IG6: =SUM(IG4+IG5) | IH6: TOTAL | IJ6: =SUM(IJ4+IJ5) | IK6: TOTAL | IM6: =SUM(IM4+IM5) | IN6: TOTAL | IP6: =SUM(IP4+IP5) | IQ6: TOTAL | IS6: =SUM(IS4+IS5) | IT6: TOTAL | IV6: =SUM(IV4+IV5) | IW6: TOTAL | IY6: =SUM(IY4+IY5) | IZ6: TOTAL | JB6: =SUM(JB4+JB5) | JC6: TOTAL | JE6: =SUM(JE4+JE5) | JF6: TOTAL | JH6: =SUM(JH4+JH5) | JI6: TOTAL | JK6: =SUM(JK4+JK5) | JL6: TOTAL | JN6: =SUM(JN4+JN5) | JO6: TOTAL | JQ6: =SUM(JQ4+JQ5) | JR6: TOTAL | JT6: =SUM(JT4+JT5) | JU6: TOTAL | JW6: =SUM(JW4+JW5) | JX6: TOTAL | JZ6: =SUM(JZ4+JZ5) | KA6: TOTAL | KC6: =SUM(KC4+KC5) | KD6: TOTAL | KF6: =SUM(KF4+KF5) | KG6: TOTAL | KI6: =SUM(KI4+KI5) | KJ6: TOTAL | KL6: =SUM(KL4+KL5) | KM6: TOTAL | KO6: =SUM(KO4+KO5) | KP6: TOTAL | KR6: =SUM(KR4+KR5) | KS6: TOTAL | KU6: =SUM(KU4+KU5) | KV6: TOTAL | KX6: =SUM(KX4+KX5) | KY6: TOTAL | LA6: =SUM(LA4+LA5) | LB6: TOTAL
A8: LAKEVILLE | D8: LAKEVILLE | G8: LAKEVILLE | J8: LAKEVILLE | M8: LAKEVILLE | P8: LAKEVILLE | S8: LAKEVILLE | V8: LAKEVILLE | Y8: LAKEVILLE | AB8: LAKEVILLE | AE8: LAKEVILLE | AH8: LAKEVILLE | AK8: LAKEVILLE | AN8: LAKEVILLE | AQ8: LAKEVILLE | AT8: LAKEVILLE | AW8: LAKEVILLE | AZ8: LAKEVILLE | BC8: LAKEVILLE | BF8: LAKEVILLE | BI8: LAKEVILLE | BL8: LAKEVILLE | BO8: LAKEVILLE | BR8: LAKEVILLE | BU8: LAKEVILLE | BX8: LAKEVILLE | CA8: LAKEVILLE | CD8: LAKEVILLE | CG8: LAKEVILLE | CJ8: LAKEVILLE | CM8: LAKEVILLE | CP8: LAKEVILLE | CS8: LAKEVILLE | CV8: LAKEVILLE | CY8: LAKEVILLE | DB8: LAKEVILLE | DE8: LAKEVILLE | DH8: LAKEVILLE | DK8: LAKEVILLE | DN8: LAKEVILLE | DQ8: LAKEVILLE | DT8: LAKEVILLE | DW8: LAKEVILLE | DZ8: LAKEVILLE | EC8: LAKEVILLE | EF8: LAKEVILLE | EI8: LAKEVILLE | EL8: LAKEVILLE | EO8: LAKEVILLE | ER8: LAKEVILLE | EU8: LAKEVILLE | EX8: LAKEVILLE | FA8: LAKEVILLE | FD8: LAKEVILLE | FG8: LAKEVILLE | FJ8: LAKEVILLE | FM8: LAKEVILLE | FP8: LAKEVILLE | FS8: LAKEVILLE | FV8: LAKEVILLE | FY8: LAKEVILLE | GB8: LAKEVILLE | GE8: LAKEVILLE | GH8: LAKEVILLE | GK8: LAKEVILLE | GN8: LAKEVILLE | GQ8: LAKEVILLE | GT8: LAKEVILLE | GW8: LAKEVILLE | GZ8: LAKEVILLE | HC8: LAKEVILLE | HF8: LAKEVILLE | HI8: LAKEVILLE | HL8: LAKEVILLE | HO8: LAKEVILLE | HR8: LAKEVILLE | HU8: LAKEVILLE | HX8: LAKEVILLE | IA8: LAKEVILLE | ID8: LAKEVILLE | IG8: LAKEVILLE | IJ8: LAKEVILLE | IM8: LAKEVILLE | IP8: LAKEVILLE | IS8: LAKEVILLE | IV8: LAKEVILLE | IY8: LAKEVILLE | JB8: LAKEVILLE | JE8: LAKEVILLE | JH8: LAKEVILLE | JK8: LAKEVILLE | JN8: LAKEVILLE | JQ8: LAKEVILLE | JT8: LAKEVILLE | JW8: LAKEVILLE | JZ8: LAKEVILLE | KC8: LAKEVILLE | KF8: LAKEVILLE | KI8: LAKEVILLE | KL8: LAKEVILLE | KO8: LAKEVILLE | KR8: LAKEVILLE | KU8: LAKEVILLE | KX8: LAKEVILLE | LA8: LAKEVILLE
A9: 32 | B9: OPEN REPAIR TICKETS | D9: 38 | E9: OPEN REPAIR TICKETS | H9: OPEN REPAIR TICKETS | K9: OPEN REPAIR TICKETS | N9: OPEN REPAIR TICKETS | Q9: OPEN REPAIR TICKETS | T9: OPEN REPAIR TICKETS | W9: OPEN REPAIR TICKETS | Z9: OPEN REPAIR TICKETS | AC9: OPEN REPAIR TICKETS | AF9: OPEN REPAIR TICKETS | AI9: OPEN REPAIR TICKETS | AL9: OPEN REPAIR TICKETS | AO9: OPEN REPAIR TICKETS | AR9: OPEN REPAIR TICKETS | AU9: OPEN REPAIR TICKETS | AX9: OPEN REPAIR TICKETS | BA9: OPEN REPAIR TICKETS | BD9: OPEN REPAIR TICKETS | BG9: OPEN REPAIR TICKETS | BJ9: OPEN REPAIR TICKETS | BM9: OPEN REPAIR TICKETS | BP9: OPEN REPAIR TICKETS | BS9: OPEN REPAIR TICKETS | BV9: OPEN REPAIR TICKETS | BY9: OPEN REPAIR TICKETS | CB9: OPEN REPAIR TICKETS | CE9: OPEN REPAIR TICKETS | CH9: OPEN REPAIR TICKETS | CK9: OPEN REPAIR TICKETS | CN9: OPEN REPAIR TICKETS | CQ9: OPEN REPAIR TICKETS | CT9: OPEN REPAIR TICKETS | CW9: OPEN REPAIR TICKETS | CZ9: OPEN REPAIR TICKETS | DC9: OPEN REPAIR TICKETS | DF9: OPEN REPAIR TICKETS | DI9: OPEN REPAIR TICKETS | DL9: OPEN REPAIR TICKETS | DO9: OPEN REPAIR TICKETS | DR9: OPEN REPAIR TICKETS | DU9: OPEN REPAIR TICKETS | DX9: OPEN REPAIR TICKETS | EA9: OPEN REPAIR TICKETS | ED9: OPEN REPAIR TICKETS | EG9: OPEN REPAIR TICKETS | EJ9: OPEN REPAIR TICKETS | EM9: OPEN REPAIR TICKETS | EP9: OPEN REPAIR TICKETS | ES9: OPEN REPAIR TICKETS | EV9: OPEN REPAIR TICKETS | EY9: OPEN REPAIR TICKETS | FB9: OPEN REPAIR TICKETS | FE9: OPEN REPAIR TICKETS | FH9: OPEN REPAIR TICKETS | FK9: OPEN REPAIR TICKETS | FN9: OPEN REPAIR TICKETS | FQ9: OPEN REPAIR TICKETS | FT9: OPEN REPAIR TICKETS | FW9: OPEN REPAIR TICKETS | FZ9: OPEN REPAIR TICKETS | GC9: OPEN REPAIR TICKETS | GF9: OPEN REPAIR TICKETS | GI9: OPEN REPAIR TICKETS | GL9: OPEN REPAIR TICKETS | GO9: OPEN REPAIR TICKETS | GR9: OPEN REPAIR TICKETS | GU9: OPEN REPAIR TICKETS | GX9: OPEN REPAIR TICKETS | HA9: OPEN REPAIR TICKETS | HD9: OPEN REPAIR TICKETS | HG9: OPEN REPAIR TICKETS | HJ9: OPEN REPAIR TICKETS | HM9: OPEN REPAIR TICKETS | HP9: OPEN REPAIR TICKETS | HS9: OPEN REPAIR TICKETS | HV9: OPEN REPAIR TICKETS | HY9: OPEN REPAIR TICKETS | IB9: OPEN REPAIR TICKETS | IE9: OPEN REPAIR TICKETS | IH9: OPEN REPAIR TICKETS | IK9: OPEN REPAIR TICKETS | IN9: OPEN REPAIR TICKETS | IQ9: OPEN REPAIR TICKETS | IT9: OPEN REPAIR TICKETS | IW9: OPEN REPAIR TICKETS | IZ9: OPEN REPAIR TICKETS | JC9: OPEN REPAIR TICKETS | JF9: OPEN REPAIR TICKETS | JI9: OPEN REPAIR TICKETS | JL9: OPEN REPAIR TICKETS | JO9: OPEN REPAIR TICKETS | JR9: OPEN REPAIR TICKETS | JU9: OPEN REPAIR TICKETS | JX9: OPEN REPAIR TICKETS | KA9: OPEN REPAIR TICKETS | KD9: OPEN REPAIR TICKETS | KG9: OPEN REPAIR TICKETS | KJ9: OPEN REPAIR TICKETS | KM9: OPEN REPAIR TICKETS | KP9: OPEN REPAIR TICKETS | KS9: OPEN REPAIR TICKETS | KV9: OPEN REPAIR TICKETS | KY9: OPEN REPAIR TICKETS | LB9: OPEN REPAIR TICKETS
A10: 173 | B10: OPEN PMS | D10: 241 | E10: OPEN PMS | H10: OPEN PMS | K10: OPEN PMS | N10: OPEN PMS | Q10: OPEN PMS | T10: OPEN PMS | W10: OPEN PMS | Z10: OPEN PMS | AC10: OPEN PMS | AF10: OPEN PMS | AI10: OPEN PMS | AL10: OPEN PMS | AO10: OPEN PMS | AR10: OPEN PMS | AU10: OPEN PMS | AX10: OPEN PMS | BA10: OPEN PMS | BD10: OPEN PMS | BG10: OPEN PMS | BJ10: OPEN PMS | BM10: OPEN PMS | BP10: OPEN PMS | BS10: OPEN PMS | BV10: OPEN PMS | BY10: OPEN PMS | CB10: OPEN PMS | CE10: OPEN PMS | CH10: OPEN PMS | CK10: OPEN PMS | CN10: OPEN PMS | CQ10: OPEN PMS | CT10: OPEN PMS | CW10: OPEN PMS | CZ10: OPEN PMS | DC10: OPEN PMS | DF10: OPEN PMS | DI10: OPEN PMS | DL10: OPEN PMS | DO10: OPEN PMS | DR10: OPEN PMS | DU10: OPEN PMS | DX10: OPEN PMS | EA10: OPEN PMS | ED10: OPEN PMS | EG10: OPEN PMS | EJ10: OPEN PMS | EM10: OPEN PMS | EP10: OPEN PMS | ES10: OPEN PMS | EV10: OPEN PMS | EY10: OPEN PMS | FB10: OPEN PMS | FE10: OPEN PMS | FH10: OPEN PMS | FK10: OPEN PMS | FN10: OPEN PMS | FQ10: OPEN PMS | FT10: OPEN PMS | FW10: OPEN PMS | FZ10: OPEN PMS | GC10: OPEN PMS | GF10: OPEN PMS | GI10: OPEN PMS | GL10: OPEN PMS | GO10: OPEN PMS | GR10: OPEN PMS | GU10: OPEN PMS | GX10: OPEN PMS | HA10: OPEN PMS | HD10: OPEN PMS | HG10: OPEN PMS | HJ10: OPEN PMS | HM10: OPEN PMS | HP10: OPEN PMS | HS10: OPEN PMS | HV10: OPEN PMS | HY10: OPEN PMS | IB10: OPEN PMS | IE10: OPEN PMS | IH10: OPEN PMS | IK10: OPEN PMS | IN10: OPEN PMS | IQ10: OPEN PMS | IT10: OPEN PMS | IW10: OPEN PMS | IZ10: OPEN PMS | JC10: OPEN PMS | JF10: OPEN PMS | JI10: OPEN PMS | JL10: OPEN PMS | JO10: OPEN PMS | JR10: OPEN PMS | JU10: OPEN PMS | JX10: OPEN PMS | KA10: OPEN PMS | KD10: OPEN PMS | KG10: OPEN PMS | KJ10: OPEN PMS | KM10: OPEN PMS | KP10: OPEN PMS | KS10: OPEN PMS | KV10: OPEN PMS | KY10: OPEN PMS | LB10: OPEN PMS
A11: =SUM(A9+A10) | B11: TOTAL | D11: =SUM(D9+D10) | E11: TOTAL | G11: =SUM(G9+G10) | H11: TOTAL | J11: =SUM(J9+J10) | K11: TOTAL | M11: =SUM(M9+M10) | N11: TOTAL | P11: =SUM(P9+P10) | Q11: TOTAL | S11: =SUM(S9+S10) | T11: TOTAL | V11: =SUM(V9+V10) | W11: TOTAL | Y11: =SUM(Y9+Y10) | Z11: TOTAL | AB11: =SUM(AB9+AB10) | AC11: TOTAL | AE11: =SUM(AE9+AE10) | AF11: TOTAL | AH11: =SUM(AH9+AH10) | AI11: TOTAL | AK11: =SUM(AK9+AK10) | AL11: TOTAL | AN11: =SUM(AN9+AN10) | AO11: TOTAL | AQ11: =SUM(AQ9+AQ10) | AR11: TOTAL | AT11: =SUM(AT9+AT10) | AU11: TOTAL | AW11: =SUM(AW9+AW10) | AX11: TOTAL | AZ11: =SUM(AZ9+AZ10) | BA11: TOTAL | BC11: =SUM(BC9+BC10) | BD11: TOTAL | BF11: =SUM(BF9+BF10) | BG11: TOTAL | BI11: =SUM(BI9+BI10) | BJ11: TOTAL | BL11: =SUM(BL9+BL10) | BM11: TOTAL | BO11: =SUM(BO9+BO10) | BP11: TOTAL | BR11: =SUM(BR9+BR10) | BS11: TOTAL | BU11: =SUM(BU9+BU10) | BV11: TOTAL | BX11: =SUM(BX9+BX10) | BY11: TOTAL | CA11: =SUM(CA9+CA10) | CB11: TOTAL | CD11: =SUM(CD9+CD10) | CE11: TOTAL | CG11: =SUM(CG9+CG10) | CH11: TOTAL | CJ11: =SUM(CJ9+CJ10) | CK11: TOTAL | CM11: =SUM(CM9+CM10) | CN11: TOTAL | CP11: =SUM(CP9+CP10) | CQ11: TOTAL | CS11: =SUM(CS9+CS10) | CT11: TOTAL | CV11: =SUM(CV9+CV10) | CW11: TOTAL | CY11: =SUM(CY9+CY10) | CZ11: TOTAL | DB11: =SUM(DB9+DB10) | DC11: TOTAL | DE11: =SUM(DE9+DE10) | DF11: TOTAL | DH11: =SUM(DH9+DH10) | DI11: TOTAL | DK11: =SUM(DK9+DK10) | DL11: TOTAL | DN11: =SUM(DN9+DN10) | DO11: TOTAL | DQ11: =SUM(DQ9+DQ10) | DR11: TOTAL | DT11: =SUM(DT9+DT10) | DU11: TOTAL | DW11: =SUM(DW9+DW10) | DX11: TOTAL | DZ11: =SUM(DZ9+DZ10) | EA11: TOTAL | EC11: =SUM(EC9+EC10) | ED11: TOTAL | EF11: =SUM(EF9+EF10) | EG11: TOTAL | EI11: =SUM(EI9+EI10) | EJ11: TOTAL | EL11: =SUM(EL9+EL10) | EM11: TOTAL | EO11: =SUM(EO9+EO10) | EP11: TOTAL | ER11: =SUM(ER9+ER10) | ES11: TOTAL | EU11: =SUM(EU9+EU10) | EV11: TOTAL | EX11: =SUM(EX9+EX10) | EY11: TOTAL | FA11: =SUM(FA9+FA10) | FB11: TOTAL | FD11: =SUM(FD9+FD10) | FE11: TOTAL | FG11: =SUM(FG9+FG10) | FH11: TOTAL | FJ11: =SUM(FJ9+FJ10) | FK11: TOTAL | FM11: =SUM(FM9+FM10) | FN11: TOTAL | FP11: =SUM(FP9+FP10) | FQ11: TOTAL | FS11: =SUM(FS9+FS10) | FT11: TOTAL | FV11: =SUM(FV9+FV10) | FW11: TOTAL | FY11: =SUM(FY9+FY10) | FZ11: TOTAL | GB11: =SUM(GB9+GB10) | GC11: TOTAL | GE11: =SUM(GE9+GE10) | GF11: TOTAL | GH11: =SUM(GH9+GH10) | GI11: TOTAL | GK11: =SUM(GK9+GK10) | GL11: TOTAL | GN11: =SUM(GN9+GN10) | GO11: TOTAL | GQ11: =SUM(GQ9+GQ10) | GR11: TOTAL | GT11: =SUM(GT9+GT10) | GU11: TOTAL | GW11: =SUM(GW9+GW10) | GX11: TOTAL | GZ11: =SUM(GZ9+GZ10) | HA11: TOTAL | HC11: =SUM(HC9+HC10) | HD11: TOTAL | HF11: =SUM(HF9+HF10) | HG11: TOTAL | HI11: =SUM(HI9+HI10) | HJ11: TOTAL | HL11: =SUM(HL9+HL10) | HM11: TOTAL | HO11: =SUM(HO9+HO10) | HP11: TOTAL | HR11: =SUM(HR9+HR10) | HS11: TOTAL | HU11: =SUM(HU9+HU10) | HV11: TOTAL | HX11: =SUM(HX9+HX10) | HY11: TOTAL | IA11: =SUM(IA9+IA10) | IB11: TOTAL | ID11: =SUM(ID9+ID10) | IE11: TOTAL | IG11: =SUM(IG9+IG10) | IH11: TOTAL | IJ11: =SUM(IJ9+IJ10) | IK11: TOTAL | IM11: =SUM(IM9+IM10) | IN11: TOTAL | IP11: =SUM(IP9+IP10) | IQ11: TOTAL | IS11: =SUM(IS9+IS10) | IT11: TOTAL | IV11: =SUM(IV9+IV10) | IW11: TOTAL | IY11: =SUM(IY9+IY10) | IZ11: TOTAL | JB11: =SUM(JB9+JB10) | JC11: TOTAL | JE11: =SUM(JE9+JE10) | JF11: TOTAL | JH11: =SUM(JH9+JH10) | JI11: TOTAL | JK11: =SUM(JK9+JK10) | JL11: TOTAL | JN11: =SUM(JN9+JN10) | JO11: TOTAL | JQ11: =SUM(JQ9+JQ10) | JR11: TOTAL | JT11: =SUM(JT9+JT10) | JU11: TOTAL | JW11: =SUM(JW9+JW10) | JX11: TOTAL | JZ11: =SUM(JZ9+JZ10) | KA11: TOTAL | KC11: =SUM(KC9+KC10) | KD11: TOTAL | KF11: =SUM(KF9+KF10) | KG11: TOTAL | KI11: =SUM(KI9+KI10) | KJ11: TOTAL | KL11: =SUM(KL9+KL10) | KM11: TOTAL | KO11: =SUM(KO9+KO10) | KP11: TOTAL | KR11: =SUM(KR9+KR10) | KS11: TOTAL | KU11: =SUM(KU9+KU10) | KV11: TOTAL | KX11: =SUM(KX9+KX10) | KY11: TOTAL | LA11: =SUM(LA9+LA10) | LB11: TOTAL
A13: COMBINED | D13: COMBINED | G13: COMBINED | J13: COMBINED | M13: COMBINED | P13: COMBINED | S13: COMBINED | V13: COMBINED | Y13: COMBINED | AB13: COMBINED | AE13: COMBINED | AH13: COMBINED | AK13: COMBINED | AN13: COMBINED | AQ13: COMBINED | AT13: COMBINED | AW13: COMBINED | AZ13: COMBINED | BC13: COMBINED | BF13: COMBINED | BI13: COMBINED | BL13: COMBINED | BO13: COMBINED | BR13: COMBINED | BU13: COMBINED | BX13: COMBINED | CA13: COMBINED | CD13: COMBINED | CG13: COMBINED | CJ13: COMBINED | CM13: COMBINED | CP13: COMBINED | CS13: COMBINED | CV13: COMBINED | CY13: COMBINED | DB13: COMBINED | DE13: COMBINED | DH13: COMBINED | DK13: COMBINED | DN13: COMBINED | DQ13: COMBINED | DT13: COMBINED | DW13: COMBINED | DZ13: COMBINED | EC13: COMBINED | EF13: COMBINED | EI13: COMBINED | EL13: COMBINED | EO13: COMBINED | ER13: COMBINED | EU13: COMBINED | EX13: COMBINED | FA13: COMBINED | FD13: COMBINED | FG13: COMBINED | FJ13: COMBINED | FM13: COMBINED | FP13: COMBINED | FS13: COMBINED | FV13: COMBINED | FY13: COMBINED | GB13: COMBINED | GE13: COMBINED | GH13: COMBINED | GK13: COMBINED | GN13: COMBINED | GQ13: COMBINED | GT13: COMBINED | GW13: COMBINED | GZ13: COMBINED | HC13: COMBINED | HF13: COMBINED | HI13: COMBINED | HL13: COMBINED | HO13: COMBINED | HR13: COMBINED | HU13: COMBINED | HX13: COMBINED | IA13: COMBINED | ID13: COMBINED | IG13: COMBINED | IJ13: COMBINED | IM13: COMBINED | IP13: COMBINED | IS13: COMBINED | IV13: COMBINED | IY13: COMBINED | JB13: COMBINED | JE13: COMBINED | JH13: COMBINED | JK13: COMBINED | JN13: COMBINED | JQ13: COMBINED | JT13: COMBINED | JW13: COMBINED | JZ13: COMBINED | KC13: COMBINED | KF13: COMBINED | KI13: COMBINED | KL13: COMBINED | KO13: COMBINED | KR13: COMBINED | KU13: COMBINED | KX13: COMBINED | LA13: COMBINED
A14: =SUM(A6+A11) | B14: TOTAL OPEN IN BOTH PLANTS | D14: =SUM(D6+D11) | E14: TOTAL OPEN IN BOTH PLANTS | G14: =SUM(G6+G11) | H14: TOTAL OPEN IN BOTH PLANTS | J14: =SUM(J6+J11) | K14: TOTAL OPEN IN BOTH PLANTS | M14: =SUM(M6+M11) | N14: TOTAL OPEN IN BOTH PLANTS | P14: =SUM(P6+P11) | Q14: TOTAL OPEN IN BOTH PLANTS | S14: =SUM(S6+S11) | T14: TOTAL OPEN IN BOTH PLANTS | V14: =SUM(V6+V11) | W14: TOTAL OPEN IN BOTH PLANTS | Y14: =SUM(Y6+Y11) | Z14: TOTAL OPEN IN BOTH PLANTS | AB14: =SUM(AB6+AB11) | AC14: TOTAL OPEN IN BOTH PLANTS | AE14: =SUM(AE6+AE11) | AF14: TOTAL OPEN IN BOTH PLANTS | AH14: =SUM(AH6+AH11) | AI14: TOTAL OPEN IN BOTH PLANTS | AK14: =SUM(AK6+AK11) | AL14: TOTAL OPEN IN BOTH PLANTS | AN14: =SUM(AN6+AN11) | AO14: TOTAL OPEN IN BOTH PLANTS | AQ14: =SUM(AQ6+AQ11) | AR14: TOTAL OPEN IN BOTH PLANTS | AT14: =SUM(AT6+AT11) | AU14: TOTAL OPEN IN BOTH PLANTS | AW14: =SUM(AW6+AW11) | AX14: TOTAL OPEN IN BOTH PLANTS | AZ14: =SUM(AZ6+AZ11) | BA14: TOTAL OPEN IN BOTH PLANTS | BC14: =SUM(BC6+BC11) | BD14: TOTAL OPEN IN BOTH PLANTS | BF14: =SUM(BF6+BF11) | BG14: TOTAL OPEN IN BOTH PLANTS | BI14: =SUM(BI6+BI11) | BJ14: TOTAL OPEN IN BOTH PLANTS | BL14: =SUM(BL6+BL11) | BM14: TOTAL OPEN IN BOTH PLANTS | BO14: =SUM(BO6+BO11) | BP14: TOTAL OPEN IN BOTH PLANTS | BR14: =SUM(BR6+BR11) | BS14: TOTAL OPEN IN BOTH PLANTS | BU14: =SUM(BU6+BU11) | BV14: TOTAL OPEN IN BOTH PLANTS | BX14: =SUM(BX6+BX11) | BY14: TOTAL OPEN IN BOTH PLANTS | CA14: =SUM(CA6+CA11) | CB14: TOTAL OPEN IN BOTH PLANTS | CD14: =SUM(CD6+CD11) | CE14: TOTAL OPEN IN BOTH PLANTS | CG14: =SUM(CG6+CG11) | CH14: TOTAL OPEN IN BOTH PLANTS | CJ14: =SUM(CJ6+CJ11) | CK14: TOTAL OPEN IN BOTH PLANTS | CM14: =SUM(CM6+CM11) | CN14: TOTAL OPEN IN BOTH PLANTS | CP14: =SUM(CP6+CP11) | CQ14: TOTAL OPEN IN BOTH PLANTS | CS14: =SUM(CS6+CS11) | CT14: TOTAL OPEN IN BOTH PLANTS | CV14: =SUM(CV6+CV11) | CW14: TOTAL OPEN IN BOTH PLANTS | CY14: =SUM(CY6+CY11) | CZ14: TOTAL OPEN IN BOTH PLANTS | DB14: =SUM(DB6+DB11) | DC14: TOTAL OPEN IN BOTH PLANTS | DE14: =SUM(DE6+DE11) | DF14: TOTAL OPEN IN BOTH PLANTS | DH14: =SUM(DH6+DH11) | DI14: TOTAL OPEN IN BOTH PLANTS | DK14: =SUM(DK6+DK11) | DL14: TOTAL OPEN IN BOTH PLANTS | DN14: =SUM(DN6+DN11) | DO14: TOTAL OPEN IN BOTH PLANTS | DQ14: =SUM(DQ6+DQ11) | DR14: TOTAL OPEN IN BOTH PLANTS | DT14: =SUM(DT6+DT11) | DU14: TOTAL OPEN IN BOTH PLANTS | DW14: =SUM(DW6+DW11) | DX14: TOTAL OPEN IN BOTH PLANTS | DZ14: =SUM(DZ6+DZ11) | EA14: TOTAL OPEN IN BOTH PLANTS | EC14: =SUM(EC6+EC11) | ED14: TOTAL OPEN IN BOTH PLANTS | EF14: =SUM(EF6+EF11) | EG14: TOTAL OPEN IN BOTH PLANTS | EI14: =SUM(EI6+EI11) | EJ14: TOTAL OPEN IN BOTH PLANTS | EL14: =SUM(EL6+EL11) | EM14: TOTAL OPEN IN BOTH PLANTS | EO14: =SUM(EO6+EO11) | EP14: TOTAL OPEN IN BOTH PLANTS | ER14: =SUM(ER6+ER11) | ES14: TOTAL OPEN IN BOTH PLANTS | EU14: =SUM(EU6+EU11) | EV14: TOTAL OPEN IN BOTH PLANTS | EX14: =SUM(EX6+EX11) | EY14: TOTAL OPEN IN BOTH PLANTS | FA14: =SUM(FA6+FA11) | FB14: TOTAL OPEN IN BOTH PLANTS | FD14: =SUM(FD6+FD11) | FE14: TOTAL OPEN IN BOTH PLANTS | FG14: =SUM(FG6+FG11) | FH14: TOTAL OPEN IN BOTH PLANTS | FJ14: =SUM(FJ6+FJ11) | FK14: TOTAL OPEN IN BOTH PLANTS | FM14: =SUM(FM6+FM11) | FN14: TOTAL OPEN IN BOTH PLANTS | FP14: =SUM(FP6+FP11) | FQ14: TOTAL OPEN IN BOTH PLANTS | FS14: =SUM(FS6+FS11) | FT14: TOTAL OPEN IN BOTH PLANTS | FV14: =SUM(FV6+FV11) | FW14: TOTAL OPEN IN BOTH PLANTS | FY14: =SUM(FY6+FY11) | FZ14: TOTAL OPEN IN BOTH PLANTS | GB14: =SUM(GB6+GB11) | GC14: TOTAL OPEN IN BOTH PLANTS | GE14: =SUM(GE6+GE11) | GF14: TOTAL OPEN IN BOTH PLANTS | GH14: =SUM(GH6+GH11) | GI14: TOTAL OPEN IN BOTH PLANTS | GK14: =SUM(GK6+GK11) | GL14: TOTAL OPEN IN BOTH PLANTS | GN14: =SUM(GN6+GN11) | GO14: TOTAL OPEN IN BOTH PLANTS | GQ14: =SUM(GQ6+GQ11) | GR14: TOTAL OPEN IN BOTH PLANTS | GT14: =SUM(GT6+GT11) | GU14: TOTAL OPEN IN BOTH PLANTS | GW14: =SUM(GW6+GW11) | GX14: TOTAL OPEN IN BOTH PLANTS | GZ14: =SUM(GZ6+GZ11) | HA14: TOTAL OPEN IN BOTH PLANTS | HC14: =SUM(HC6+HC11) | HD14: TOTAL OPEN IN BOTH PLANTS | HF14: =SUM(HF6+HF11) | HG14: TOTAL OPEN IN BOTH PLANTS | HI14: =SUM(HI6+HI11) | HJ14: TOTAL OPEN IN BOTH PLANTS | HL14: =SUM(HL6+HL11) | HM14: TOTAL OPEN IN BOTH PLANTS | HO14: =SUM(HO6+HO11) | HP14: TOTAL OPEN IN BOTH PLANTS | HR14: =SUM(HR6+HR11) | HS14: TOTAL OPEN IN BOTH PLANTS | HU14: =SUM(HU6+HU11) | HV14: TOTAL OPEN IN BOTH PLANTS | HX14: =SUM(HX6+HX11) | HY14: TOTAL OPEN IN BOTH PLANTS | IA14: =SUM(IA6+IA11) | IB14: TOTAL OPEN IN BOTH PLANTS | ID14: =SUM(ID6+ID11) | IE14: TOTAL OPEN IN BOTH PLANTS | IG14: =SUM(IG6+IG11) | IH14: TOTAL OPEN IN BOTH PLANTS | IJ14: =SUM(IJ6+IJ11) | IK14: TOTAL OPEN IN BOTH PLANTS | IM14: =SUM(IM6+IM11) | IN14: TOTAL OPEN IN BOTH PLANTS | IP14: =SUM(IP6+IP11) | IQ14: TOTAL OPEN IN BOTH PLANTS | IS14: =SUM(IS6+IS11) | IT14: TOTAL OPEN IN BOTH PLANTS | IV14: =SUM(IV6+IV11) | IW14: TOTAL OPEN IN BOTH PLANTS | IY14: =SUM(IY6+IY11) | IZ14: TOTAL OPEN IN BOTH PLANTS | JB14: =SUM(JB6+JB11) | JC14: TOTAL OPEN IN BOTH PLANTS | JE14: =SUM(JE6+JE11) | JF14: TOTAL OPEN IN BOTH PLANTS | JH14: =SUM(JH6+JH11) | JI14: TOTAL OPEN IN BOTH PLANTS | JK14: =SUM(JK6+JK11) | JL14: TOTAL OPEN IN BOTH PLANTS | JN14: =SUM(JN6+JN11) | JO14: TOTAL OPEN IN BOTH PLANTS | JQ14: =SUM(JQ6+JQ11) | JR14: TOTAL OPEN IN BOTH PLANTS | JT14: =SUM(JT6+JT11) | JU14: TOTAL OPEN IN BOTH PLANTS | JW14: =SUM(JW6+JW11) | JX14: TOTAL OPEN IN BOTH PLANTS | JZ14: =SUM(JZ6+JZ11) | KA14: TOTAL OPEN IN BOTH PLANTS | KC14: =SUM(KC6+KC11) | KD14: TOTAL OPEN IN BOTH PLANTS | KF14: =SUM(KF6+KF11) | KG14: TOTAL OPEN IN BOTH PLANTS | KI14: =SUM(KI6+KI11) | KJ14: TOTAL OPEN IN BOTH PLANTS | KL14: =SUM(KL6+KL11) | KM14: TOTAL OPEN IN BOTH PLANTS | KO14: =SUM(KO6+KO11) | KP14: TOTAL OPEN IN BOTH PLANTS | KR14: =SUM(KR6+KR11) | KS14: TOTAL OPEN IN BOTH PLANTS | KU14: =SUM(KU6+KU11) | KV14: TOTAL OPEN IN BOTH PLANTS | KX14: =SUM(KX6+KX11) | KY14: TOTAL OPEN IN BOTH PLANTS | LA14: =SUM(LA6+LA11) | LB14: TOTAL OPEN IN BOTH PLANTS
A15: NOTE | D15: NOTE | G15: NOTE | J15: NOTE | M15: NOTE | P15: NOTE | S15: NOTE | V15: NOTE | Y15: NOTE | AB15: NOTE | AE15: NOTE | AH15: NOTE | AK15: NOTE | AN15: NOTE | AQ15: NOTE | AT15: NOTE | AW15: NOTE | AZ15: NOTE | BC15: NOTE | BF15: NOTE | BI15: NOTE | BL15: NOTE | BO15: NOTE | BR15: NOTE | BU15: NOTE | BX15: NOTE | CA15: NOTE | CD15: NOTE | CG15: NOTE | CJ15: NOTE | CM15: NOTE | CP15: NOTE | CS15: NOTE | CV15: NOTE | CY15: NOTE | DB15: NOTE | DE15: NOTE | DH15: NOTE | DK15: NOTE | DN15: NOTE | DQ15: NOTE | DT15: NOTE | DW15: NOTE | DZ15: NOTE | EC15: NOTE | EF15: NOTE | EI15: NOTE | EL15: NOTE | EO15: NOTE | ER15: NOTE | EU15: NOTE | EX15: NOTE | FA15: NOTE | FD15: NOTE | FG15: NOTE | FJ15: NOTE | FM15: NOTE | FP15: NOTE | FS15: NOTE | FV15: NOTE | FY15: NOTE | GB15: NOTE | GE15: NOTE | GH15: NOTE | GK15: NOTE | GN15: NOTE | GQ15: NOTE | GT15: NOTE | GW15: NOTE | GZ15: NOTE | HC15: NOTE | HF15: NOTE | HI15: NOTE | HL15: NOTE | HO15: NOTE | HR15: NOTE | HU15: NOTE | HX15: NOTE | IA15: NOTE | ID15: NOTE | IG15: NOTE | IJ15: NOTE | IM15: NOTE | IP15: NOTE | IS15: NOTE | IV15: NOTE | IY15: NOTE | JB15: NOTE | JE15: NOTE | JH15: NOTE | JK15: NOTE | JN15: NOTE | JQ15: NOTE | JT15: NOTE | JW15: NOTE | JZ15: NOTE | KC15: NOTE | KF15: NOTE | KI15: NOTE | KL15: NOTE | KO15: NOTE | KR15: NOTE | KU15: NOTE | KX15: NOTE | LA15: NOTE
A17: HOW TO UPDATE
A18: 1. Type this week's four counts into the blue cells of the block whose date matches this week. TOTAL rows and the History tab fill themselves.
A19: 2. A block still blank after its date has passed turns yellow, so you can see what you missed.
A20: 3. Row 15 of each block is a free-text NOTE. Anything you type there shows up in the Notes column of the weekly log, next to that week.
A21: 4. Blocks are pre-built through September 11, 2028. See the Read Me tab to add more.
A22: =HYPERLINK("#Totals!"&ADDRESS(4,$B$33,4),"► Jump to this week's block")
A30: =IF(AND(A$1="DATE",ISNUMBER(B$1),COUNT(A4,A5,A9,A10)=4),1,0) | B30: =IF(AND(B$1="DATE",ISNUMBER(C$1),COUNT(B4,B5,B9,B10)=4),1,0) | C30: =IF(AND(C$1="DATE",ISNUMBER(D$1),COUNT(C4,C5,C9,C10)=4),1,0) | D30: =IF(AND(D$1="DATE",ISNUMBER(E$1),COUNT(D4,D5,D9,D10)=4),1,0) | E30: =IF(AND(E$1="DATE",ISNUMBER(F$1),COUNT(E4,E5,E9,E10)=4),1,0) | F30: =IF(AND(F$1="DATE",ISNUMBER(G$1),COUNT(F4,F5,F9,F10)=4),1,0) | G30: =IF(AND(G$1="DATE",ISNUMBER(H$1),COUNT(G4,G5,G9,G10)=4),1,0) | H30: =IF(AND(H$1="DATE",ISNUMBER(I$1),COUNT(H4,H5,H9,H10)=4),1,0) | ... OJ30: =IF(AND(OJ$1="DATE",ISNUMBER(OK$1),COUNT(OJ4,OJ5,OJ9,OJ10)=4),1,0)
A31: =IF(A30=1,SUM($A$30:A30),"") | B31: =IF(B30=1,SUM($A$30:B30),"") | C31: =IF(C30=1,SUM($A$30:C30),"") | D31: =IF(D30=1,SUM($A$30:D30),"") | E31: =IF(E30=1,SUM($A$30:E30),"") | F31: =IF(F30=1,SUM($A$30:F30),"") | G31: =IF(G30=1,SUM($A$30:G30),"") | H31: =IF(H30=1,SUM($A$30:H30),"") | ... OJ31: =IF(OJ30=1,SUM($A$30:OJ30),"")
A32: =IF(A$1="DATE",COUNTIF($A$1:A$1,"DATE"),"") | B32: =IF(B$1="DATE",COUNTIF($A$1:B$1,"DATE"),"") | C32: =IF(C$1="DATE",COUNTIF($A$1:C$1,"DATE"),"") | D32: =IF(D$1="DATE",COUNTIF($A$1:D$1,"DATE"),"") | E32: =IF(E$1="DATE",COUNTIF($A$1:E$1,"DATE"),"") | F32: =IF(F$1="DATE",COUNTIF($A$1:F$1,"DATE"),"") | G32: =IF(G$1="DATE",COUNTIF($A$1:G$1,"DATE"),"") | H32: =IF(H$1="DATE",COUNTIF($A$1:H$1,"DATE"),"") | ... OJ32: =IF(OJ$1="DATE",COUNTIF($A$1:OJ$1,"DATE"),"")
A33: =MAX(1,COUNTIF($A$1:$OJ$1,"<="&TODAY())) | B33: =IFERROR(MATCH($A$33,$A$32:$OJ$32,0),1) | C33: =COUNTIF($A$1:$OJ$1,"DATE") | D33: =COUNTIF($1:$1,"DATE") | E33: =SUM($A$34:$OJ$34) | F33: =SUM($A$35:$OJ$35)
A34: =IF(AND(A$1="DATE",COUNT(A4,A5,A9,A10)>0,A30=0),1,0) | B34: =IF(AND(B$1="DATE",COUNT(B4,B5,B9,B10)>0,B30=0),1,0) | C34: =IF(AND(C$1="DATE",COUNT(C4,C5,C9,C10)>0,C30=0),1,0) | D34: =IF(AND(D$1="DATE",COUNT(D4,D5,D9,D10)>0,D30=0),1,0) | E34: =IF(AND(E$1="DATE",COUNT(E4,E5,E9,E10)>0,E30=0),1,0) | F34: =IF(AND(F$1="DATE",COUNT(F4,F5,F9,F10)>0,F30=0),1,0) | G34: =IF(AND(G$1="DATE",COUNT(G4,G5,G9,G10)>0,G30=0),1,0) | H34: =IF(AND(H$1="DATE",COUNT(H4,H5,H9,H10)>0,H30=0),1,0) | ... OJ34: =IF(AND(OJ$1="DATE",COUNT(OJ4,OJ5,OJ9,OJ10)>0,OJ30=0),1,0)
A35: =IF(AND(A$1="DATE",ISNUMBER(B$1),COUNTIF($A$1:$OJ$1,B$1)>1),1,0) | B35: =IF(AND(B$1="DATE",ISNUMBER(C$1),COUNTIF($A$1:$OJ$1,C$1)>1),1,0) | C35: =IF(AND(C$1="DATE",ISNUMBER(D$1),COUNTIF($A$1:$OJ$1,D$1)>1),1,0) | D35: =IF(AND(D$1="DATE",ISNUMBER(E$1),COUNTIF($A$1:$OJ$1,E$1)>1),1,0) | E35: =IF(AND(E$1="DATE",ISNUMBER(F$1),COUNTIF($A$1:$OJ$1,F$1)>1),1,0) | F35: =IF(AND(F$1="DATE",ISNUMBER(G$1),COUNTIF($A$1:$OJ$1,G$1)>1),1,0) | G35: =IF(AND(G$1="DATE",ISNUMBER(H$1),COUNTIF($A$1:$OJ$1,H$1)>1),1,0) | H35: =IF(AND(H$1="DATE",ISNUMBER(I$1),COUNTIF($A$1:$OJ$1,I$1)>1),1,0) | ... OJ35: =IF(AND(OJ$1="DATE",ISNUMBER(OK$1),COUNTIF($A$1:$OJ$1,OK$1)>1),1,0)

Sheet Read Me
B2: OPEN WORK ORDERS TRACKER — READ ME
B4: WHAT THIS FILE IS
B5: One row per week showing how many work orders are open at Burnsville and at Lakeville, split into repair tickets and PMs. It answers the standing question: is the backlog growing or shrinking?
B6: You type four numbers a week, on the Totals tab. Everything else — totals, the change since the last entry, the charts, the scorecard and the email text — is calculated. The History tab is the one you send.
B8: THE WEEKLY ROUTINE
B9: Step 1 | C9: Pull the open work order counts for both plants.
B10: Step 2 | C10: Open the Totals tab. The link under the grid jumps to the block whose date is this week.
B11: Step 3 | C11: Type all four counts into the blue cells: repair tickets and PMs for Burnsville, then the same two for Lakeville. A week is only picked up once all four are in, so a half-filled block is left out rather than reported as zeros.
B12: Step 4 | C12: If a number moved for a reason worth remembering, type it into the NOTE row of that same block. It shows up in the Notes column of the weekly log.
B13: Step 5 | C13: Go to the History tab and read the top. If a red bar has appeared under the headline, fix what it names before you send anything.
B14: Step 6 | C14: Copy the email box (to the right of the charts) into your weekly email. In Outlook, paste with Keep Text Only, or you will paste a one-cell table. Send the file link with it.
B16: READING THE NUMBERS
B17: Repair tickets and PMs are counted separately on purpose. PMs are scheduled work: when the maintenance system releases a new batch, the PM count jumps by dozens overnight without anything going wrong on the floor.
B18: Repair tickets are the number that reflects real, unplanned backlog. When you are asked whether things are getting better or worse, that is the line to look at.
B19: ▲ means more open than the previous entry, ▼ means fewer. The arrow carries the meaning, so it reads correctly in black and white and for a colourblind reader. Only the repair rows are coloured red and green, because a rising PM count usually means a batch was released, not that anything went wrong.
B20: The 4-week average column answers "is this week normal?". A single week bounces around; the average is what tells you whether the level has actually moved.
B21: There is one chart per plant, plus one for the two together. They are split that way because Lakeville runs about twenty times higher than Burnsville: any chart holding both plants' PM counts would flatten Burnsville onto the axis and show nothing. In every chart blue is repair tickets, orange is PMs, and dark grey is the two added together.
B22: The charts show the most recent 26 weeks so they stay readable as the file fills up. Every week ever recorded is in the log underneath them.
B24: CONVENTIONS
B25: "Count Date" is the date the count was actually pulled, which is normally a Monday. The first entry, 09-15-2026, was pulled on a Tuesday and is left as it was recorded rather than tidied.
